Workbook

Sheet Echipamente
A1: Nut Technology (Ucraina) – echipamente procesare nuci, alune, migdale – broșuri, capacități și caracteristici (sursa: nuttechnology.com/brochure-download, extras 28.09.2026)
A2: Producție kg/zi și t/an se calculează automat din parametrii din foaia „Linie ideala” (ore/zi, zile/an). Uscătoarele lucrează în șarje de 24h; utilajele de sezon (decojire/uscare) folosesc zilele de sezon.
A4: Nr. | B4: Etapa proces | C4: Denumire echipament (RO) | D4: Denumire originală (EN) | E4: Capacitate (declarată pe site) | F4: Capacitate kg/h (calcul) | G4: Regim funcționare | H4: Producție kg/zi | I4: Producție t/an | J4: % miez întreg | K4: Putere motor | L4: Tensiune | M4: Material | N4: Potrivit pentru | O4: Descriere (site producător) | P4: Pagina produs (RO) | Q4: Pagina produs (EN) | R4: Link broșură pe site | S4: Fișier salvat local | T4: Observații
A5: 1 | B5: Recoltare | C5: Scuturător pentru pomi fructiferi | D5: Fruit tree shaker | G5: — | M5: oțel | N5: nuci, alune, migdale, mere, pruni și alți pomi fructiferi | O5: Scuturătorul pentru pomi fructiferi este un echipament special pentru scuturarea rapidă a fructelor coapte din copaci. Acesta facilitează procesul de recoltare de la orice tip de pomi, economisește energie, reduce semnificativ timpul necesar pentru efectuarea acestei lucrări dificile și previne ruperea ramurilor. | P5: https://nuttechnology.com/ro/produs/agitator-de-pomi-fructiferi/ | Q5: https://nuttechnology.com/product/fruit-tree-shaker/ | R5: https://nuttechnology.com/wp-content/uploads/FRUIT-TREE-SHAKER_compressed.pdf | S5: Z:\00. Proiecte 2025\AFIR FotoVoltaic 1\50. Fabrica Nuci\nuttechnology.com\Brosuri echipamente\01. Recoltare\01. Scuturător pentru pomi fructiferi.pdf
A6: 2 | B6: Decojire coaja verde si spalare | C6: Mașină de decojire și curățare a nucilor verzi 100 kg/h | D6: Green walnut peeling and cleaning machine 100 kg/h | E6: până la 100 kg/h | F6: 100 | G6: continuu – sezon | H6: =F6*'Linie ideala'!$C$6 | I6: =H6*'Linie ideala'!$C$8/1000 | K6: 0.75 kW | L6: 220 V | M6: oțel | N6: nuci, alune, migdale | O6: Mașina de decojire și curățare a nucilor verzi 100 kg/h este un echipament pentru decojirea de înaltă calitate a nucilor de pericarpul verde. Aceasta îndepărtează cu ușurință coaja verde de pe nucile tinere și coapte, lăsând coaja intactă. | P6: https://nuttechnology.com/ro/produs/ma-in-de-cur-at-i-decojit-nuci-verzi-100-kg-h/ | Q6: https://nuttechnology.com/product/green-walnut-peeling-and-cleaning-machine-100-kg-h/ | R6: https://nuttechnology.com/wp-content/uploads/Green-walnut-peeling-and-cleaning-100-kg_h.pdf | S6: Z:\00. Proiecte 2025\AFIR FotoVoltaic 1\50. Fabrica Nuci\nuttechnology.com\Brosuri echipamente\02. Decojire coaja verde si spalare\01. Mașină de decojire și curățare a nucilor verzi 100 kg-h.pdf
A7: 3 | B7: Decojire coaja verde si spalare | C7: Mașină pentru decojirea și curățarea nucilor verzi 300 kg/h | D7: Green walnut peeling and cleaning machine 300 kg/h | E7: până la 300 kg/h | F7: 300 | G7: continuu – sezon | H7: =F7*'Linie ideala'!$C$6 | I7: =H7*'Linie ideala'!$C$8/1000 | K7: 1.1 kW | L7: 220 V | M7: oțel | N7: nuci, alune, migdale | O7: Mașina de decojire a nucilor verzi este un utilaj special pentru curățarea nucilor de pericarpul verde. Aceasta îndepărtează coaja verde atât de pe nucile tinere abia coapte, cât și de pe cele a căror coajă s-a desprins deja. Datorită mașinii de decojire, coaja nucilor rămâne intactă, fără ciobituri sau deteriorări, fiind pregătită pentru o procesare ulterioară de înaltă calitate. | P7: https://nuttechnology.com/ro/produs/ma-in-de-cur-at-i-decojit-nuci-verzi-300-kg-h/ | Q7: https://nuttechnology.com/product/green-walnut-peeling-and-cleaning-machine-300-kg-h/ | R7: https://nuttechnology.com/wp-content/uploads/Green-walnut-peeling-and-cleaning-300-kg_h.pdf | S7: Z:\00. Proiecte 2025\AFIR FotoVoltaic 1\50. Fabrica Nuci\nuttechnology.com\Brosuri echipamente\02. Decojire coaja verde si spalare\02. Mașină pentru decojirea și curățarea nucilor verzi 300 kg-h.pdf
A8: 4 | B8: Decojire coaja verde si spalare | C8: Mașină de decojire și curățare a nucilor verzi 700 kg/h | D8: Green walnut peeling and cleaning machine 700 kg/h | E8: până la 700 kg/h | F8: 700 | G8: continuu – sezon | H8: =F8*'Linie ideala'!$C$6 | I8: =H8*'Linie ideala'!$C$8/1000 | K8: 2.2 kW | L8: 220 V | M8: oțel | N8: nuci, alune, migdale | O8: Echipamentul este utilizat în livezi industriale. Datorită formei conice a buncărului și dinților ascuțiți din oțel, utilajul curăță rapid volume mari de nuci (până la 700 kg pe oră) de pericarpul verde. | P8: https://nuttechnology.com/ro/produs/ma-in-de-cur-at-i-decojit-nuci-verzi-700-kg-h/ | Q8: https://nuttechnology.com/product/green-walnut-peeling-and-cleaning-machine-700-kg-h/ | R8: https://nuttechnology.com/wp-content/uploads/Green-walnut-peeling-and-cleaning-700-kg_h.pdf | S8: Z:\00. Proiecte 2025\AFIR FotoVoltaic 1\50. Fabrica Nuci\nuttechnology.com\Brosuri echipamente\02. Decojire coaja verde si spalare\03. Mașină de decojire și curățare a nucilor verzi 700 kg-h.pdf
A9: 5 | B9: Decojire coaja verde si spalare | C9: Mașină industrială de decojire și spălare (1 t/h) | D9: Industrial peeling and washing machine (1 t/h) | E9: până la 1 t/h | F9: 1000 | G9: continuu – sezon | H9: =F9*'Linie ideala'!$C$6 | I9: =H9*'Linie ideala'!$C$8/1000 | K9: 3.7 kW | L9: 220 V | M9: oțel | N9: nuci, alune, migdale | O9: Spălătorul industrial cu tambur pentru decojirea și spălarea nucilor de pericarpul verde este cel mai rapid și versatil dintre echipamentele noastre de decojire. Îndepărtează coaja verde de pe nucile tinere, proaspăt coapte, precum și de pe nucile la care pericarpul se desprinde singur. După spălare, coaja nucii rămâne intactă, iar nucile sunt trimise la uscare. | P9: https://nuttechnology.com/ro/produs/ma-in-industrial-de-cur-are-i-sp-lare-1-t-h/ | Q9: https://nuttechnology.com/product/industrial-peeling-and-washing-machine-1-t-h/ | R9: https://nuttechnology.com/wp-content/uploads/Industrial-peeling-and-washing-machine-1-th.pdf | S9: Z:\00. Proiecte 2025\AFIR FotoVoltaic 1\50. Fabrica Nuci\nuttechnology.com\Brosuri echipamente\02. Decojire coaja verde si spalare\04. Mașină industrială de decojire și spălare (1 t-h).pdf
A10: 6 | B10: Decojire coaja verde si spalare | C10: Mașină pentru îndepărtarea cojii verzi a alunelor | D10: Hazelnut green husk remover machine | E10: până la 300 kg/h | F10: 300 | G10: continuu – sezon | H10: =F10*'Linie ideala'!$C$6 | I10: =H10*'Linie ideala'!$C$8/1000 | K10: 2.2 kW | L10: 220 V | M10: oțel | N10: nuci, alune, migdale | O10: Echipamentele optimizează procesarea alunelor și asigură pregătirea acestora pentru diverse utilizări, cum ar fi vânzarea sau prelucrarea ulterioară. | P10: https://nuttechnology.com/ro/produs/ma-in-de-cur-at-coaja-verde-de-alune/ | Q10: https://nuttechnology.com/product/hazelnut-green-husk-remover-machine/ | R10: https://nuttechnology.com/wp-content/uploads/Hazelnut-green-husk-remover-machine_.pdf | S10: Z:\00. Proiecte 2025\AFIR FotoVoltaic 1\50. Fabrica Nuci\nuttechnology.com\Brosuri echipamente\02. Decojire coaja verde si spalare\05. Mașină pentru îndepărtarea cojii verzi a alunelor.pdf
A11: 7 | B11: Uscare si incarcare uscator | C11: Uscător pentru nuci, alune și migdale în coajă (până la 1 tonă/24 ore) | D11: Dryer for inshell walnuts, hazelnuts, almonds (up to 1 ton/24 hours) | E11: până la 1 t/zi | F11: 41.7 | G11: șarjă 24h – sezon | H11: =F11*24 | I11: =H11*'Linie ideala'!$C$8/1000 | K11: 12 kW | L11: 380 V | M11: oțel | N11: nuci, alune, migdale | O11: Uscătorul este un echipament indispensabil pentru proprietarii de livezi industriale, întreprinderi de achiziții și unități de procesare. Acesta este utilizat pentru uscarea nucilor, alunelor, migdalelor și a altor tipuri de nuci. | P11: https://nuttechnology.com/ro/produs/usc-tor-pentru-nuci-nep-jite-alune-migdale-capacitate-p-n-la-1-ton-24-ore/ | Q11: https://nuttechnology.com/product/dryer-for-inshell-walnuts-hazelnuts-almonds-up-to-1-ton-24-hours/ | R11: https://nuttechnology.com/wp-content/uploads/Dryer-for-walnuts-hazelnuts-almonds-1-ton_.pdf | S11: Z:\00. Proiecte 2025\AFIR FotoVoltaic 1\50. Fabrica Nuci\nuttechnology.com\Brosuri echipamente\03. Uscare si incarcare uscator\01. Uscător pentru nuci, alune și migdale în coajă (până la 1 tonă-24 ore).pdf
A12: 8 | B12: Uscare si incarcare uscator | C12: Uscător pentru nuci, alune și migdale în coajă (până la 2 tone/24 ore) | D12: Dryer for inshell walnuts, hazelnuts, almonds (up to 2 ton/24 hours) | E12: până la 2 t/24h (titlu); site: 1 t/zi | F12: 83.3 | G12: șarjă 24h – sezon | H12: =F12*24 | I12: =H12*'Linie ideala'!$C$8/1000 | K12: 12 kW | L12: 380 V | M12: oțel | N12: nuci, alune, migdale | O12: Uscătorul este un echipament indispensabil pentru proprietarii de livezi industriale, întreprinderi de achiziții și unități de procesare. Acesta este utilizat pentru uscarea nucilor, alunelor, migdalelor și a altor tipuri de nuci. | P12: https://nuttechnology.com/ro/produs/usc-tor-pentru-nuci-decojite-alune-migdale-capacitate-p-n-la-2-tone-pe-24-de-ore/ | Q12: https://nuttechnology.com/product/dryer-for-inshell-walnuts-hazelnuts-almonds-up-to-2-ton-24-hours/ | R12: https://nuttechnology.com/wp-content/uploads/Dryer-for-walnuts-hazelnuts-almonds-1-ton_.pdf | S12: Z:\00. Proiecte 2025\AFIR FotoVoltaic 1\50. Fabrica Nuci\nuttechnology.com\Brosuri echipamente\03. Uscare si incarcare uscator\02. Uscător pentru nuci, alune și migdale în coajă (până la 2 tone-24 ore).pdf | T12: Pe site, broșura atașată este cea a uscătorului de 1 t/24h (nu există broșură separată pt. 2 t). Specificația de pe site indică tot „până la 1 t/zi” – de clarificat cu producătorul.
A13: 9 | B13: Uscare si incarcare uscator | C13: Uscător pentru nuci, alune și migdale în coajă (2 tone/zi) | D13: Dryer for walnuts, hazelnuts, and almonds in shell (2 tons/day) | E13: până la 2 t/zi | F13: 83.3 | G13: șarjă 24h – sezon | H13: =F13*24 | I13: =H13*'Linie ideala'!$C$8/1000 | K13: 14 kW | L13: 380 V | M13: oțel | N13: nuci, alune, migdale | O13: Uscătorul este un echipament indispensabil pentru proprietarii de livezi industriale, întreprinderi de achiziții și unități de procesare a nucilor. Acesta este utilizat pentru uscarea nucilor, alunelor, migdalelor și a altor tipuri de nuci. | P13: https://nuttechnology.com/ro/produs/usc-tor-pentru-nuci-alune-i-migdale-n-coaj/ | Q13: https://nuttechnology.com/product/dryer-for-walnuts-hazelnuts-and-almonds-in-shell/ | R13: https://nuttechnology.com/wp-content/uploads/DRYER-FOR-INSHELL-WALNUTS.pdf | S13: Z:\00. Proiecte 2025\AFIR FotoVoltaic 1\50. Fabrica Nuci\nuttechnology.com\Brosuri echipamente\03. Uscare si incarcare uscator\03. Uscător pentru nuci, alune și migdale în coajă (2 tone-zi).pdf
A14: 10 | B14: Uscare si incarcare uscator | C14: Uscător pentru nuci, alune și migdale în coajă (4 tone/zi) | D14: Dryer for walnuts, hazelnuts, and almonds in shell (4 tons/day) | E14: până la 4 t/zi | F14: 166.7 | G14: șarjă 24h – sezon | H14: =F14*24 | I14: =H14*'Linie ideala'!$C$8/1000 | K14: 14 kW | L14: 380 V | M14: oțel | N14: nuci, alune, migdale | O14: Uscătorul este un echipament indispensabil pentru proprietarii de livezi industriale, întreprinderi de achiziții și unități de procesare a nucilor. Acesta este utilizat pentru uscarea nucilor, alunelor, migdalelor și a altor tipuri de nuci. | P14: https://nuttechnology.com/ro/produs/usc-tor-pentru-nuci-alune-i-migdale-n-coaj-2/ | Q14: https://nuttechnology.com/product/dryer-for-walnuts-hazelnuts-and-almonds-in-shell-2/ | R14: https://nuttechnology.com/wp-content/uploads/DRYER-FOR-INSHELL-WALNUTS-4-tons.pdf | S14: Z:\00. Proiecte 2025\AFIR FotoVoltaic 1\50. Fabrica Nuci\nuttechnology.com\Brosuri echipamente\03. Uscare si incarcare uscator\04. Uscător pentru nuci, alune și migdale în coajă (4 tone-zi).pdf | T14: Pe site câmpul „Material” este completat greșit („Ukraine”); corect: oțel.
A15: 11 | B15: Uscare si incarcare uscator | C15: Conveyor de alimentare pentru uscător 2 t/zi | D15: Dryer feed conveyor for dryer 2 t/day | G15: transport/încărcare | K15: 0.55 kW | L15: 220 / 380 V | M15: oțel, PVC | N15: nuci, alune, migdale | O15: Acest conveyor este utilizat pentru încărcarea nucilor în uscător. Asigură o alimentare simplă și rapidă a nucilor, cu efort minim. | P15: https://nuttechnology.com/ro/produs/band-de-alimentare-usc-tor/ | Q15: https://nuttechnology.com/product/dryer-feed-conveyor/ | R15: https://nuttechnology.com/wp-content/uploads/Loading-conveyor.pdf | S15: Z:\00. Proiecte 2025\AFIR FotoVoltaic 1\50. Fabrica Nuci\nuttechnology.com\Brosuri echipamente\03. Uscare si incarcare uscator\05. Conveyor de alimentare pentru uscător 2 t-zi.pdf | T15: Broșură comună cu banda pentru uscătorul 4 t/h.
A16: 12 | B16: Uscare si incarcare uscator | C16: Conveyor de alimentare pentru uscător 4 t/h | D16: Dryer feed conveyor for dryer 4 t/h | E16: 4 t/h (din denumire) | F16: 4000 | G16: transport/încărcare | H16: — | I16: — | K16: 0.55 kW | L16: 220 / 380 V | M16: oțel, PVC | N16: nuci, alune, migdale | O16: Acest conveyor este utilizat pentru încărcarea nucilor în uscător. Asigură o alimentare simplă și rapidă a nucilor, cu efort minim. | P16: https://nuttechnology.com/ro/produs/band-transportoare-de-alimentare-pentru-usc-tor-4-t-h/ | Q16: https://nuttechnology.com/product/dryer-feed-conveyor-for-dryer-4-t-h/ | R16: https://nuttechnology.com/wp-content/uploads/Loading-conveyor.pdf | S16: Z:\00. Proiecte 2025\AFIR FotoVoltaic 1\50. Fabrica Nuci\nuttechnology.com\Brosuri echipamente\03. Uscare si incarcare uscator\06. Conveyor de alimentare pentru uscător 4 t-h.pdf | T16: Broșură comună cu banda pentru uscătorul 2 t/zi.
A17: 13 | B17: Uscare si incarcare uscator | C17: Elevator cu încărcare/descărcare Noria 2 tone pe oră | D17: Noria Load/Unload Elevator 2 tons per hour | E17: 2 t/h (din denumire) | F17: 2000 | G17: transport/încărcare | H17: — | I17: — | L17: 220 / 380 V | M17: oțel | N17: nuci, alune, migdale | O17: Elevatorul industrial este proiectat pentru transport vertical eficient al produselor vrac și de dimensiuni mici, cum ar fi nuci, cereale, fructe de pădure, peleți și materiale similare. Echipat cu funcție de mișcare reversibilă, permite atât operațiuni de încărcare, cât și de descărcare în cadrul procesului tehnologic, asigurând versatilitate și integrare ușoară în liniile de producție. | P17: https://nuttechnology.com/ro/produs/elevator-noria-pentru-nc-rcare-desc-rcare-de-2-tone-pe-or/ | Q17: https://nuttechnology.com/product/noria-load-unload-elevator-2-tons-per-hour/ | R17: https://nuttechnology.com/wp-content/uploads/Loading-conveyor.pdf | S17: Z:\00. Proiecte 2025\AFIR FotoVoltaic 1\50. Fabrica Nuci\nuttechnology.com\Brosuri echipamente\03. Uscare si incarcare uscator\07. Elevator cu încărcare-descărcare Noria 2 tone pe oră.pdf | T17: Site-ul trimite la broșura „Loading conveyor” (bandă de alimentare uscător) – nu există broșură dedicată pentru elevatorul Noria.
A18: 14 | B18: Uscare si incarcare uscator | C18: Elevator cu încărcare/descărcare Noria 4 tone pe oră | D18: Noria Load/Unload Elevator 4 tons per hour | E18: 4 t/h (din denumire) | F18: 4000 | G18: transport/încărcare | H18: — | I18: — | L18: 220 / 380 V | M18: oțel | N18: nuci, alune, migdale | O18: Elevatorul industrial este proiectat pentru transport vertical eficient al produselor vrac și de dimensiuni mici, cum ar fi nuci, cereale, fructe de pădure, peleți și materiale similare. Echipat cu funcție de mișcare reversibilă, permite atât operațiuni de încărcare, cât și de descărcare în cadrul procesului tehnologic, asigurând versatilitate și integrare ușoară în liniile de producție. | P18: https://nuttechnology.com/ro/produs/norie-de-nc-rcare-desc-rcare-elevator-4-tone-pe-or/ | Q18: https://nuttechnology.com/product/noria-load-unload-elevator-4-tons-per-hour/ | R18: https://nuttechnology.com/wp-content/uploads/Loading-conveyor.pdf | S18: Z:\00. Proiecte 2025\AFIR FotoVoltaic 1\50. Fabrica Nuci\nuttechnology.com\Brosuri echipamente\03. Uscare si incarcare uscator\08. Elevator cu încărcare-descărcare Noria 4 tone pe oră.pdf | T18: Site-ul trimite la broșura „Loading conveyor” (bandă de alimentare uscător) – nu există broșură dedicată pentru elevatorul Noria.
A19: 15 | B19: Calibrare si sortare in coaja | C19: Calibrator liniar pentru toate tipurile de nuci | D19: Line calibrator for all sorts of nuts | E19: până la 100 kg/h | F19: 100 | G19: continuu – tot anul | H19: =F19*'Linie ideala'!$C$5 | I19: =H19*'Linie ideala'!$C$7/1000 | K19: 0.55 kW | L19: 220 / 380 V | M19: oțel | N19: nuci, migdale | O19: Calibratorul este un echipament destinat sortării rapide a nucilor în coajă după dimensiune; datorită setărilor flexibile, este ideal pentru calibrarea nucilor, alunelor, migdalelor și chiar a melcilor, iar calibrarea este esențială în întreprinderile medii și mari pentru procesarea de înaltă calitate a nucilor cu ajutorul mașinilor industriale de spart nuci. | P19: https://nuttechnology.com/ro/produs/calibrator-de-linie-pentru-toate-tipurile-de-piuli-e/ | Q19: https://nuttechnology.com/product/line-calibrator-for-all-sorts-of-nuts/ | R19: https://nuttechnology.com/wp-content/uploads/Line-calibrator-for-all-sorts-of-nuts.pdf | S19: Z:\00. Proiecte 2025\AFIR FotoVoltaic 1\50. Fabrica Nuci\nuttechnology.com\Brosuri echipamente\04. Calibrare si sortare in coaja\01. Calibrator liniar pentru toate tipurile de nuci.pdf
A20: 16 | B20: Calibrare si sortare in coaja | C20: Mașină de calibrare a nucilor în 4 fracții | D20: Walnut calibrating machine 4 fractions | E20: până la 300 kg/h | F20: 300 | G20: continuu – tot anul | H20: =F20*'Linie ideala'!$C$5 | I20: =H20*'Linie ideala'!$C$7/1000 | K20: 0.55 kW | L20: 220 V | M20: oțel | N20: nuci | O20: Mașina de calibrare a nucilor este utilizată în livezile de nuci și în fabricile de procesare; calibratorul este o parte necesară a liniei de producție, facilitând procesarea ulterioară și crescând randamentul miezului întreg. | P20: https://nuttechnology.com/ro/produs/ma-in-de-calibrare-nuci/ | Q20: https://nuttechnology.com/product/walnut-calibrating-machine/ | R20: https://nuttechnology.com/wp-content/uploads/WALNUT-CALIBRATING-MACHINE-4-fractions.pdf | S20: Z:\00. Proiecte 2025\AFIR FotoVoltaic 1\50. Fabrica Nuci\nuttechnology.com\Brosuri echipamente\04. Calibrare si sortare in coaja\02. Mașină de calibrare a nucilor în 4 fracții.pdf
A21: 17 | B21: Calibrare si sortare in coaja | C21: Mașină de calibrare a nucilor în 8 fracții | D21: Walnut calibrating machine 8 fractions | E21: până la 500 kg/h | F21: 500 | G21: continuu – tot anul | H21: =F21*'Linie ideala'!$C$5 | I21: =H21*'Linie ideala'!$C$7/1000 | K21: 2.95 kW | L21: 380 V | M21: oțel | N21: nuci | O21: Mașina de calibrare a nucilor este un instrument esențial atât pentru livezile de nuci, cât și pentru unitățile de procesare; prin sortarea nucilor în 8 fracții distincte, acest calibrator optimizează etapele ulterioare de procesare și crește randamentul miezului întreg, devenind un element indispensabil al liniei de producție. | P21: https://nuttechnology.com/ro/produs/ma-in-de-calibrat-nuci-8-frac-iuni/ | Q21: https://nuttechnology.com/product/walnut-calibrating-machine-8-fractions/ | R21: https://nuttechnology.com/wp-content/uploads/WALNUT-CALIBRATING-MACHINE-8-fractions.pdf | S21: Z:\00. Proiecte 2025\AFIR FotoVoltaic 1\50. Fabrica Nuci\nuttechnology.com\Brosuri echipamente\04. Calibrare si sortare in coaja\03. Mașină de calibrare a nucilor în 8 fracții.pdf
A22: 18 | B22: Calibrare si sortare in coaja | C22: Mașină pentru sortarea nucilor goale în coajă | D22: Machine for sorting empty walnut in shell | E22: până la 300 kg/h | F22: 300 | G22: continuu – tot anul | H22: =F22*'Linie ideala'!$C$5 | I22: =H22*'Linie ideala'!$C$7/1000 | K22: 4.5 kW | L22: 380 V | M22: oțel | N22: nuci, alune, migdale | O22: Această mașină de sortare abordează eficient problema respingerii produselor, crește productivitatea și eficiența procesului de producție, reduce costurile de muncă și minimizează pierderile, devenind astfel un activ valoros pentru întreprinderile de procesare a nucilor și asigurând rezultate optime și operațiuni eficiente. | P22: https://nuttechnology.com/ro/produs/ma-in-de-sortat-nuci-goale-n-coaj/ | Q22: https://nuttechnology.com/product/machine-for-sorting-empty-walnut-in-shell/ | R22: https://nuttechnology.com/wp-content/uploads/MACHINE-FOR-SORTING-EMPTY-WALNUT-IN-SHELL.pdf | S22: Z:\00. Proiecte 2025\AFIR FotoVoltaic 1\50. Fabrica Nuci\nuttechnology.com\Brosuri echipamente\04. Calibrare si sortare in coaja\04. Mașină pentru sortarea nucilor goale în coajă.pdf
A23: 19 | B23: Calibrare si sortare in coaja | C23: Mașină de calibrare a alunelor | D23: Hazelnut calibrating machine | E23: până la 200 kg/h | F23: 200 | G23: continuu – tot anul | H23: =F23*'Linie ideala'!$C$5 | I23: =H23*'Linie ideala'!$C$7/1000 | K23: 1.1 kW | L23: 220 V | M23: oțel | N23: nuci, alune, migdale | O23: Mașina de calibrare a alunelor este utilizată în livezile de alune și în fabricile de procesare. Calibratorul reprezintă o parte necesară a liniei de producție, facilitând procesarea ulterioară și crescând randamentul miezului întreg. | P23: https://nuttechnology.com/ro/produs/ma-in-de-calibrare-alune/ | Q23: https://nuttechnology.com/product/hazelnut-calibrating-machine/ | R23: https://nuttechnology.com/wp-content/uploads/Hazelnut-Calibrating-Machine.pdf | S23: Z:\00. Proiecte 2025\AFIR FotoVoltaic 1\50. Fabrica Nuci\nuttechnology.com\Brosuri echipamente\04. Calibrare si sortare in coaja\05. Mașină de calibrare a alunelor.pdf
A24: 20 | B24: Calibrare si sortare in coaja | C24: Mașină de calibrare a alunelor în 3 fracții | D24: Hazelnut calibrating machine 3 fractions | E24: până la 200 kg/h | F24: 200 | G24: continuu – tot anul | H24: =F24*'Linie ideala'!$C$5 | I24: =H24*'Linie ideala'!$C$7/1000 | K24: 0.75 kW | L24: 380 V | M24: oțel | N24: alune | O24: Mașina de calibrare a alunelor este un instrument esențial atât pentru livezile de alune, cât și pentru unitățile de procesare. Prin sortarea alunelor în 2 fracții distincte, acest calibrator optimizează etapele ulterioare de procesare și crește randamentul miezului întreg, devenind un element indispensabil al liniei de producție. | P24: https://nuttechnology.com/ro/produs/ma-in-de-calibrare-alune-3-frac-iuni/ | Q24: https://nuttechnology.com/product/hazelnut-calibrating-machine-3-fractions/ | R24: https://nuttechnology.com/wp-content/uploads/HAZELNUT-CALIBRATING-MACHINE-8-fractions.pdf | S24: Z:\00. Proiecte 2025\AFIR FotoVoltaic 1\50. Fabrica Nuci\nuttechnology.com\Brosuri echipamente\04. Calibrare si sortare in coaja\06. Mașină de calibrare a alunelor în 3 fracții.pdf | T24: Site-ul trimite la broșura calibratorului de alune 8 fracții (nu există broșură separată pt. 3 fracții).
A25: 21 | B25: Calibrare si sortare in coaja | C25: Mașină de calibrare a alunelor în 8 fracții | D25: Hazelnut calibrating machine 8 fractions | E25: până la 500 kg/h | F25: 500 | G25: continuu – tot anul | H25: =F25*'Linie ideala'!$C$5 | I25: =H25*'Linie ideala'!$C$7/1000 | K25: 2.95 kW | L25: 380 V | M25: oțel | N25: alune | O25: Mașina de calibrare a alunelor este un instrument esențial atât pentru livezile de alune, cât și pentru unitățile de procesare. Prin sortarea alunelor în 8 fracții distincte, acest calibrator optimizează etapele ulterioare de procesare și crește randamentul miezului întreg, devenind un element indispensabil al liniei de producție. | P25: https://nuttechnology.com/ro/produs/ma-in-de-calibrat-alune-8-frac-iuni/ | Q25: https://nuttechnology.com/product/hazelnut-calibrating-machine-8-fractions/ | R25: https://nuttechnology.com/wp-content/uploads/HAZELNUT-CALIBRATING-MACHINE-8-fractions.pdf | S25: Z:\00. Proiecte 2025\AFIR FotoVoltaic 1\50. Fabrica Nuci\nuttechnology.com\Brosuri echipamente\04. Calibrare si sortare in coaja\07. Mașină de calibrare a alunelor în 8 fracții.pdf | T25: Broșură comună cu calibratorul de alune 3 fracții.
A26: 22 | B26: Spargere | C26: Mașină de spart nuci 50 kg/h | D26: Walnut cracking machine 50 kg/h | E26: până la 50 kg/h | F26: 50 | G26: continuu – tot anul | H26: =F26*'Linie ideala'!$C$5 | I26: =H26*'Linie ideala'!$C$7/1000 | J26: până la 90% | K26: 0.55 kW | L26: 220 V | N26: nuci | O26: Mașina de spart nuci cu o capacitate de 50 kg/h este o soluție compactă pentru procesarea nucilor în întreprinderi mici. Se bazează pe principiul spargerii conice și nu necesită calibrarea nucilor. Sparge coaja cu grijă și asigură un randament de până la 80% miezuri întregi. | P26: https://nuttechnology.com/ro/produs/utilaj-spargere-nuci-50-kg-h/ | Q26: https://nuttechnology.com/product/walnut-cracking-machine-50-kg-h/ | R26: https://nuttechnology.com/wp-content/uploads/Walnut-cracking-machine-50-kg_h.pdf | S26: Z:\00. Proiecte 2025\AFIR FotoVoltaic 1\50. Fabrica Nuci\nuttechnology.com\Brosuri echipamente\05. Spargere\01. Mașină de spart nuci 50 kg-h.pdf
A27: 23 | B27: Spargere | C27: Mașină de spart nuci 100 kg/h | D27: Walnut cracking machine 100 kg/h | E27: până la 100 kg/h | F27: 100 | G27: continuu – tot anul | H27: =F27*'Linie ideala'!$C$5 | I27: =H27*'Linie ideala'!$C$7/1000 | J27: până la 80% | K27: 0.55 kW | L27: 220 V | N27: nuci | O27: Mașina de spart nuci 100 kg/h este un echipament indispensabil pentru procesarea de înaltă calitate a nucilor la scară industrială. Spărgătorul asigură spargerea delicată a cojii cu un randament maxim de miez întreg și este potrivit pentru procesarea nucilor de orice dimensiune. | P27: https://nuttechnology.com/ro/produs/ma-in-de-spart-nuci-100-kg-h/ | Q27: https://nuttechnology.com/product/walnut-cracking-machine-100-kg-h/ | R27: https://nuttechnology.com/wp-content/uploads/Walnut-cracking-machine-100-kg_h.pdf | S27: Z:\00. Proiecte 2025\AFIR FotoVoltaic 1\50. Fabrica Nuci\nuttechnology.com\Brosuri echipamente\05. Spargere\02. Mașină de spart nuci 100 kg-h.pdf
A28: 24 | B28: Spargere | C28: Mașină de spart nuci 200 kg/h | D28: Walnut cracking machine 200 kg/h | E28: până la 200 kg/h | F28: 200 | G28: continuu – tot anul | H28: =F28*'Linie ideala'!$C$5 | I28: =H28*'Linie ideala'!$C$7/1000 | J28: până la 80% | K28: 1.5 kW | L28: 380 V | N28: nuci | O28: Mașină de spart nuci – echipament pentru spargerea rapidă și productivă a nucilor, utilizat în întreprinderi mari și medii. Se deosebește de alte spărgătoare industriale prin productivitatea maximă. Acest model este echipat cu un mecanism de spargere de tip conic, prin care randamentul miezului întreg ajunge până la 80%. | P28: https://nuttechnology.com/ro/produs/ma-in-de-spart-nuci-200-kg-h/ | Q28: https://nuttechnology.com/product/walnut-cracking-machine-200-kg-h/ | R28: https://nuttechnology.com/wp-content/uploads/Walnut-cracking-machine-200-kg_h.pdf | S28: Z:\00. Proiecte 2025\AFIR FotoVoltaic 1\50. Fabrica Nuci\nuttechnology.com\Brosuri echipamente\05. Spargere\03. Mașină de spart nuci 200 kg-h.pdf
A29: 25 | B29: Spargere | C29: Mașină industrială de spart nuci cu coloană de aspirație integrată (200 kg/h) | D29: Industrial Walnut Nutcracker with Built-in Aspiration Column (200 kg/h) | E29: până la 200 kg/h | F29: 200 | G29: continuu – tot anul | H29: =F29*'Linie ideala'!$C$5 | I29: =H29*'Linie ideala'!$C$7/1000 | J29: până la 80% | K29: 2.05 kW | L29: 380 V | N29: nuci | O29: Mașină de spart nuci cu coloană de aspirație integrată – echipament pentru spargerea rapidă și productivă a nucilor, utilizat în întreprinderi mari și medii. Se deosebește de alte spărgătoare industriale prin productivitatea maximă. Acest model este echipat cu un mecanism de spargere de tip conic, prin care randamentul miezului întreg ajunge până la 80%, precum și cu aspirație integrată, care realizează separarea primară a cojii și a membranelor de miez. Toate acestea facilitează ulterior sortarea nucilor pe sită vibrantă cu aspirație sau sortarea manuală. | P29: https://nuttechnology.com/ro/produs/sp-rg-tor-de-nuci-industrial-din-lemn-de-nuc-cu-coloan-de-aspira-ie-ncorporat-200-kg-h/ | Q29: https://nuttechnology.com/product/industrial-walnut-nutcracker-with-built-in-aspiration-column-200-kg-h/ | R29: https://nuttechnology.com/wp-content/uploads/INDUSTRIAL-WALNUT-NUTCRACKER-WITH-BUILT-IN-ASPIRATION-COLUMN-200-KG_H_compressed.pdf | S29: Z:\00. Proiecte 2025\AFIR FotoVoltaic 1\50. Fabrica Nuci\nuttechnology.com\Brosuri echipamente\05. Spargere\04. Mașină industrială de spart nuci cu coloană de aspirație integrată (200 kg-h).pdf
A30: 26 | B30: Spargere | C30: Spărgător de nuci pentru etapa post-spărgere | D30: Walnut breaker after cracking machine | E30: până la 200 kg/h | F30: 200 | G30: continuu – tot anul | H30: =F30*'Linie ideala'!$C$5 | I30: =H30*'Linie ideala'!$C$7/1000 | K30: 1.1 kW | L30: 380 V | N30: nuci, alune, migdale | O30: Spărgătorul de nuci este utilizat pentru a reduce munca manuală și a accelera procesul de procesare. Acesta este ideal atât pentru spargerea nucilor cu coajă groasă, cât și a nucilor umede. | P30: https://nuttechnology.com/ro/produs/sp-rg-tor-de-nuci-dup-ma-ina-de-spart/ | Q30: https://nuttechnology.com/product/walnut-breaker-after-cracking-machine/ | R30: https://nuttechnology.com/wp-content/uploads/Walnut-breaker-after-cracking-machine_.pdf | S30: Z:\00. Proiecte 2025\AFIR FotoVoltaic 1\50. Fabrica Nuci\nuttechnology.com\Brosuri echipamente\05. Spargere\05. Spărgător de nuci pentru etapa post-spărgere.pdf
A31: 27 | B31: Spargere | C31: Spărgător cu tambur pentru alune și migdale | D31: Drum nutcracker for hazelnuts and almonds | E31: până la 200 kg/h | F31: 200 | G31: continuu – tot anul | H31: =F31*'Linie ideala'!$C$5 | I31: =H31*'Linie ideala'!$C$7/1000 | J31: până la 90% | K31: 1.1 kW | L31: 380 V | N31: alune, migdale | O31: Un spărgător de nuci este utilizat pentru a minimiza munca manuală și a accelera procesul de prelucrare. Spărgătorul cu tambur este excelent pentru spargerea alunelor și migdalelor la scară industrială, oferind un randament ridicat de miezuri întregi. | P31: https://nuttechnology.com/ro/produs/fructier-pentru-nuci-alune-i-migdale/ | Q31: https://nuttechnology.com/product/drum-nutcracker-for-hazelnuts-and-almonds/ | R31: https://nuttechnology.com/wp-content/uploads/DRUM-NUTCRACKER-FOR-HAZELNUTS-AND-ALMONDS_.pdf | S31: Z:\00. Proiecte 2025\AFIR FotoVoltaic 1\50. Fabrica Nuci\nuttechnology.com\Brosuri echipamente\05. Spargere\06. Spărgător cu tambur pentru alune și migdale.pdf | T31: Pe site mai apare o intrare duplicat (ID 6138) cu pagină inexistentă.
A32: 28 | B32: Spargere | C32: Spărgător de alune cu aspirație (200 kg/h) | D32: Hazelnuts Nutcracker with Aspiration (200 kg/h) | E32: până la 200 kg/h | F32: 200 | G32: continuu – tot anul | H32: =F32*'Linie ideala'!$C$5 | I32: =H32*'Linie ideala'!$C$7/1000 | J32: până la 90% | K32: 1.1 kW | L32: 380 V | N32: alune, migdale | O32: Mașină combinată care sparge alunele și curăță instant miezul cu un flux puternic de aer. Mecanismul cu tambur asigură o spargere delicată, iar aspirația integrată elimină peste 90% din coji și praf. Alimentarea prin vibrații asigură o funcționare stabilă, fără intervenție constantă. Rezultat: miez curat, procesare rapidă, efort minim. | P32: https://nuttechnology.com/ro/produs/sp-rg-tor-de-alune-cu-aspira-ie-200-kg-h/ | Q32: https://nuttechnology.com/product/hazelnuts-nutcracker-with-aspiration-200-kg-h/ | R32: https://nuttechnology.com/wp-content/uploads/DRUM-NUTCRACKER-FOR-HAZELNUTS-AND-ALMONDS_.pdf | S32: Z:\00. Proiecte 2025\AFIR FotoVoltaic 1\50. Fabrica Nuci\nuttechnology.com\Brosuri echipamente\05. Spargere\07. Spărgător de alune cu aspirație (200 kg-h).pdf | T32: Broșură comună cu spărgătorul cu tambur pentru alune și migdale (fără coloană de aspirație).
A33: 29 | B33: Separare miez si sortare | C33: Mașină pentru separarea miezului de coajă (100 kg/h) | D33: Machine for separating kernel from the shell (100 kg/h) | E33: până la 100 kg/h | F33: 100 | G33: continuu – tot anul | H33: =F33*'Linie ideala'!$C$5 | I33: =H33*'Linie ideala'!$C$7/1000 | K33: 0.55 kW | L33: 220 V | M33: oțel | N33: nuci, alune, migdale | O33: Mașina pentru separarea miezului de coajă este un echipament destinat separării cojilor, membranelor, prafului și reziduurilor din miezul de nucă. Cu ajutorul unei coloane de aspirație, procesarea nucilor este accelerată semnificativ, iar calitatea randamentului de miez crește (miezul nu conține praf, fragmente de membrane sau coajă). | P33: https://nuttechnology.com/ro/produs/ma-in-de-separat-miezul-de-coaj-100-kg-h/ | Q33: https://nuttechnology.com/product/machine-for-separating-kernel-from-the-shell-100-kg-h/ | R33: https://nuttechnology.com/wp-content/uploads/Machine-for-separating-kernel-from-the-shell-100-kg_h.pdf | S33: Z:\00. Proiecte 2025\AFIR FotoVoltaic 1\50. Fabrica Nuci\nuttechnology.com\Brosuri echipamente\06. Separare miez si sortare\01. Mașină pentru separarea miezului de coajă (100 kg-h).pdf
A34: 30 | B34: Separare miez si sortare | C34: Mașină pentru separarea miezului de coajă (300 kg/h) | D34: Machine for separating kernel from the shell (300 kg/h) | E34: până la 300 kg/h | F34: 300 | G34: continuu – tot anul | H34: =F34*'Linie ideala'!$C$5 | I34: =H34*'Linie ideala'!$C$7/1000 | K34: 1.5 kW | L34: 220 / 380 V | M34: oțel | N34: nuci, alune, migdale | O34: Mașina pentru separarea miezului de coajă este un echipament destinat separării cojilor, membranelor, prafului și reziduurilor din miezul de nucă. Cu ajutorul unei coloane de aspirație, procesarea nucilor este accelerată semnificativ, iar calitatea randamentului de miez crește (miezul nu conține praf, fragmente de membrane sau coajă). | P34: https://nuttechnology.com/ro/produs/ma-in-pentru-separarea-miezului-de-coaj-300-kg-h/ | Q34: https://nuttechnology.com/product/machine-for-separating-kernel-from-the-shell-300-kg-h/ | R34: https://nuttechnology.com/wp-content/uploads/Machine-for-separating-kernel-from-the-shell-300-kg_h.pdf | S34: Z:\00. Proiecte 2025\AFIR FotoVoltaic 1\50. Fabrica Nuci\nuttechnology.com\Brosuri echipamente\06. Separare miez si sortare\02. Mașină pentru separarea miezului de coajă (300 kg-h).pdf
A35: 31 | B35: Separare miez si sortare | C35: Mașină pentru separarea miezului de nucă (200 kg/h) | D35: Walnut kernel separating machine (200 kg/h) | E35: până la 200 kg/h | F35: 200 | G35: continuu – tot anul | H35: =F35*'Linie ideala'!$C$5 | I35: =H35*'Linie ideala'!$C$7/1000 | K35: 0.55 kW | L35: 220 / 380 V | M35: oțel | N35: nuci, alune, migdale | O35: Sita vibrantă accelerează și facilitează procesul de sortare a miezului după dimensiune. Mașina este indispensabilă în întreprinderile industriale pentru procesarea nucilor. | P35: https://nuttechnology.com/ro/produs/ma-in-de-separat-miez-de-nuc-200-kg-h/ | Q35: https://nuttechnology.com/product/walnut-kernel-separating-machine-200-kg-h/ | R35: https://nuttechnology.com/wp-content/uploads/Walnut-kernel-separating-machine-200-kg_h.pdf | S35: Z:\00. Proiecte 2025\AFIR FotoVoltaic 1\50. Fabrica Nuci\nuttechnology.com\Brosuri echipamente\06. Separare miez si sortare\03. Mașină pentru separarea miezului de nucă (200 kg-h).pdf
A36: 32 | B36: Separare miez si sortare | C36: Sit vibratoare cu aspirație pentru sortarea nucilor (200 kg/h) | D36: Vibrating sieve with aspiration for sorting walnuts (200 kg/h) | E36: până la 200 kg/h | F36: 200 | G36: continuu – tot anul | H36: =F36*'Linie ideala'!$C$5 | I36: =H36*'Linie ideala'!$C$7/1000 | K36: 1.9 kW | L36: 380 V | M36: oțel | N36: nuci, alune, migdale | O36: Sita vibrantă cu aspirație accelerează și facilitează procesul de sortare a miezului după dimensiune și separarea miezului de coajă. Instalația este indispensabilă în întreprinderile industriale pentru procesarea nucilor. | P36: https://nuttechnology.com/ro/produs/sita-vibratoare-cu-aspiratie-pentru-sortat-nuci-200-kg-h/ | Q36: https://nuttechnology.com/product/vibrating-sieve-with-aspiration-for-sorting-walnuts-200-kg-h/ | R36: https://nuttechnology.com/wp-content/uploads/Vibrating-sieve-with-aspiration-for-sorting-walnut-kernels-200-kg-h.pdf | S36: Z:\00. Proiecte 2025\AFIR FotoVoltaic 1\50. Fabrica Nuci\nuttechnology.com\Brosuri echipamente\06. Separare miez si sortare\04. Sit vibratoare cu aspirație pentru sortarea nucilor (200 kg-h).pdf
A37: 33 | B37: Separare miez si sortare | C37: Sit vibratoare cu aspirație pentru sortarea nucilor (300 kg/h) | D37: Vibrating sieve with aspiration for sorting walnuts (300 kg/h) | E37: până la 300 kg/h | F37: 300 | G37: continuu – tot anul | H37: =F37*'Linie ideala'!$C$5 | I37: =H37*'Linie ideala'!$C$7/1000 | K37: 3 kW | L37: 380 V | M37: oțel | N37: nuci, alune, migdale | O37: Când vine vorba de producția de nuci, utilizarea unei site vibrante cu sistem de aspirație este esențială; acest echipament automatizat simplifică procesul de sortare, crește eficiența și asigură funcționarea neîntreruptă. | P37: https://nuttechnology.com/ro/produs/sit-vibrant-cu-aspira-ie-pentru-sortat-nuci-300-kg-h/ | Q37: https://nuttechnology.com/product/vibrating-sieve-with-aspiration-for-sorting-walnuts-300-kg-h/ | R37: https://nuttechnology.com/wp-content/uploads/Vibrating-sieve-with-aspiration-for-sorting-walnut-kernels-300-kg_h.pdf | S37: Z:\00. Proiecte 2025\AFIR FotoVoltaic 1\50. Fabrica Nuci\nuttechnology.com\Brosuri echipamente\06. Separare miez si sortare\05. Sit vibratoare cu aspirație pentru sortarea nucilor (300 kg-h).pdf
A38: 34 | B38: Separare miez si sortare | C38: Transportor elevatoare pentru nuci | D38: Lifting conveyor for walnut | G38: — | K38: 0.55 kW | L38: 220 / 380 V | M38: oțel, PVC | N38: nuci, alune, migdale | O38: Automatizarea producției este imposibilă fără un transportor; acesta reduce numărul de angajați, accelerează și facilitează procesul de producție. | P38: https://nuttechnology.com/ro/produs/transportor-liftant-pentru-nuci/ | Q38: https://nuttechnology.com/product/lifting-conveyor-for-walnut/ | R38: https://nuttechnology.com/wp-content/uploads/Lifting-conveyor-for-walnut.pdf | S38: Z:\00. Proiecte 2025\AFIR FotoVoltaic 1\50. Fabrica Nuci\nuttechnology.com\Brosuri echipamente\06. Separare miez si sortare\06. Transportor elevatoare pentru nuci.pdf
A39: 35 | B39: Separare miez si sortare | C39: Masă de inspecție cu bandă | D39: Belt inspection table | G39: — | K39: 0.55 kW | L39: 220 / 380 V | M39: oțel, PVC | N39: nuci, alune, migdale | O39: Masa de inspecție este utilizată pentru controlul vizual al calității produsului finit; acesta este un pas important și final al procesării înainte de ambalare. | P39: https://nuttechnology.com/ro/produs/masa-de-inspec-ie-a-curelelor/ | Q39: https://nuttechnology.com/product/belt-inspection-table/ | R39: https://nuttechnology.com/wp-content/uploads/Belt-inspection-table_compressed.pdf | S39: Z:\00. Proiecte 2025\AFIR FotoVoltaic 1\50. Fabrica Nuci\nuttechnology.com\Brosuri echipamente\06. Separare miez si sortare\07. Masă de inspecție cu bandă.pdf
A40: 36 | B40: Separare miez si sortare | C40: Masă de inspecție cu bandă pe două niveluri | D40: Two-level belt inspection table | G40: — | K40: 1.1 kW | L40: 220/380 V | M40: oțel, PVC | N40: nuci | O40: Masa de inspecție este utilizată pentru controlul vizual al calității produsului finit; acesta este un pas important și final al procesării înainte de ambalare. | P40: https://nuttechnology.com/ro/produs/mas-de-inspec-ie-cu-band-cu-dou-niveluri/ | Q40: https://nuttechnology.com/product/two-level-belt-inspection-table/ | R40: https://nuttechnology.com/wp-content/uploads/Two-level-belt-inspection-table.pdf | S40: Z:\00. Proiecte 2025\AFIR FotoVoltaic 1\50. Fabrica Nuci\nuttechnology.com\Brosuri echipamente\06. Separare miez si sortare\08. Masă de inspecție cu bandă pe două niveluri.pdf
A41: 37 | B41: Sortatoare optice | C41: Sortator optic IR-63 | D41: Color Sorter IR-63 | E41: până la 200 kg/h | F41: 200 | G41: continuu – tot anul | H41: =F41*'Linie ideala'!$C$5 | I41: =H41*'Linie ideala'!$C$7/1000 | J41: până la 99,5% | K41: 1.1 kW | L41: 220 V | N41: nuci, alune, migdale | O41: Sortator optic pentru separarea cojilor de nuci și sortarea miezului după culoare; mașina de sortare cu infraroșu este o soluție avansată pentru separarea cu înaltă precizie și eficiență a cojii de miez, iar datorită inteligenței artificiale integrate oferă o acuratețe impresionantă de până la 99,9%, fiind ideală pentru nuci, alune, arahide, fasole, mazăre și alte leguminoase, semințe de floarea-soarelui, semințe de dovleac, fructe uscate, porumb și alte produse vrac. | P41: https://nuttechnology.com/ro/produs/sortator-de-culori-ir-63/ | Q41: https://nuttechnology.com/product/color-sorter-ir-63/ | R41: — (link greșit pe site) | T41: Site-ul trimite GREȘIT la broșura spărgătorului cu tambur pt. alune/migdale – nu există broșură PDF pentru acest sortator; de cerut de la producător.
...

Sheet Linie ideala
A1: Linie ideală MAXIMĂ de procesare nuci (nucă verde → miez sortat) – echipamente Nut Technology cu cea mai mare capacitate pe fiecare etapă
A2: Debitul țintă al liniei = capacitatea celui mai mare utilaj ales (mașina industrială de decojire și spălare, 1 t/h). Celelalte etape sunt multiplicate astfel încât niciuna să nu devină gâtuire. Celulele galbene sunt parametri – se pot modifica, totul se recalculează.
A4: PARAMETRI
A5: Ore de lucru pe zi – procesare (calibrare → sortare miez) | C5: 8 | D5: ore/zi | E5: Presupus 8 h/zi (1 schimb). Pentru 2 schimburi = 16, non-stop = 24.
A6: Ore de lucru pe zi – în sezon (decojire coajă verde) | C6: =C5 | D6: ore/zi | E6: Implicit egal cu programul de procesare.
A7: Zile de procesare pe an | C7: 250 | D7: zile/an | E7: Nuca uscată se poate depozita și procesa tot anul.
A8: Zile sezon recoltare (decojire + uscare) | C8: 45 | D8: zile/an | E8: Sept.–oct.; toată nuca anului trebuie decojită și uscată în această perioadă.
A9: Randament miez din nucă uscată în coajă | C9: 0.45 | D9: % | E9: Nuci: tipic 40–50%; de ajustat după soi.
A10: Debit țintă linie (nucă uscată în coajă) | C10: =MAX(E16,E17,E19:E25) | D10: kg/h | E10: =cea mai mare capacitate unitară din linie (utilajele de transport excluse). Se poate suprascrie cu o valoare fixă.
A11: Volum anual nucă uscată în coajă | C11: =C10*C5*C7/1000 | D11: t/an | E11: =debit × ore/zi × zile procesare
A14: CONFIGURAȚIA LINIEI
A15: Nr. | B15: Etapa | C15: Echipament ales (cel mai mare de pe etapă) | D15: Alternative mai mici (neselectate) | E15: Capacitate unitară kg/h | F15: Regulă dimensionare | G15: Nr. bucăți necesare | H15: Capacitate instalată kg/h | I15: Grad încărcare | J15: Putere unitară kW | K15: Putere totală kW | L15: Ore funcționare/zi | M15: Consum kWh/zi | N15: Zile/an | O15: Consum kWh/an | P15: Broșură (fișier local) | Q15: Observații
A16: 1 | B16: Decojire coajă verde + spălare | C16: Mașină industrială de decojire și spălare (1 t/h) | D16: Decojire nuci verzi 700 / 300 / 100 kg/h | E16: 1000 | F16: Volum anual ÷ (zile sezon × ore sezon) | G16: =ROUNDUP($C$11*1000/($C$8*$C$6)/E16,0) | H16: =G16*E16 | I16: =$C$11*1000/($C$8*$C$6)/H16 | J16: 3.7 | K16: =G16*J16 | L16: =$C$6 | M16: =K16*L16 | N16: =$C$8 | O16: =M16*N16 | P16: deschide broșura | Q16: Tot volumul anului trebuie decojit în sezon. Capacitatea e considerată raportată la nuca decojită – de confirmat cu producătorul.
A17: 2 | B17: Uscare nucă în coajă | C17: Uscător pentru nuci, alune și migdale în coajă (4 tone/zi) | D17: Uscătoare 2 t/zi și 1 t/zi | E17: 166.67 | F17: Volum anual ÷ (zile sezon × 4 t/zi) | G17: =ROUNDUP($C$11*1000/$C$8/(E17*24),0) | H17: =G17*E17 | I17: =$C$11*1000/$C$8/24/H17 | J17: 14 | K17: =G17*J17 | L17: 24 | M17: =K17*L17 | N17: =$C$8 | O17: =M17*N17 | P17: deschide broșura | Q17: Șarjă 24h, 4 t/zi/uscător, încălzire ELECTRICĂ 14 kW – principalul consumator pentru sistemul fotovoltaic. Dimensionat: volum anual ÷ zile sezon.
A18: 3 | B18: Încărcare uscătoare | C18: Conveyor de alimentare pentru uscător 4 t/h | D18: Bandă pentru uscător 2 t/zi; elevator Noria 4 t/h (alternativă) | E18: 4000 | F18: 1 buc. / uscător | G18: =G17 | H18: =G18*E18 | I18: — | J18: 0.55 | K18: =G18*J18 | L18: 1 | M18: =K18*L18 | N18: =$C$8 | O18: =M18*N18 | P18: deschide broșura | Q18: 1 bandă de alimentare per uscător (recomandarea producătorului). Estimat 1 h funcționare/zi.
A19: 4 | B19: Calibrare nucă în coajă | C19: Mașină de calibrare a nucilor în 8 fracții | D19: Calibrator 4 fracții 300 kg/h; calibrator liniar 100 kg/h | E19: 500 | F19: Debit țintă ÷ capacitate unitară | G19: =ROUNDUP($C$10/E19,0) | H19: =G19*E19 | I19: =$C$10/H19 | J19: 2.95 | K19: =G19*J19 | L19: =$C$5 | M19: =K19*L19 | N19: =$C$7 | O19: =M19*N19 | P19: deschide broșura | Q19: 8 fracții – crește randamentul de miez întreg la spargere.
A20: 5 | B20: Eliminare nuci goale | C20: Mașină pentru sortarea nucilor goale în coajă | D20: — | E20: 300 | F20: Debit țintă ÷ capacitate unitară | G20: =ROUNDUP($C$10/E20,0) | H20: =G20*E20 | I20: =$C$10/H20 | J20: 4.5 | K20: =G20*J20 | L20: =$C$5 | M20: =K20*L20 | N20: =$C$7 | O20: =M20*N20 | P20: deschide broșura
A21: 6 | B21: Spargere | C21: Mașină industrială de spart nuci cu coloană de aspirație integrată (200 kg/h) | D21: Spărgător 200 kg/h fără aspirație; 100 / 50 kg/h | E21: 200 | F21: Debit țintă ÷ capacitate unitară | G21: =ROUNDUP($C$10/E21,0) | H21: =G21*E21 | I21: =$C$10/H21 | J21: 2.05 | K21: =G21*J21 | L21: =$C$5 | M21: =K21*L21 | N21: =$C$7 | O21: =M21*N21 | P21: deschide broșura | Q21: Etapa limitativă: cel mai mare spărgător are doar 200 kg/h → se multiplică.
A22: 7 | B22: Spargere secundară (post-spărgere) | C22: Spărgător de nuci pentru etapa post-spărgere | D22: — | E22: 200 | F22: Debit țintă ÷ capacitate unitară | G22: =ROUNDUP($C$10/E22,0) | H22: =G22*E22 | I22: =$C$10/H22 | J22: 1.1 | K22: =G22*J22 | L22: =$C$5 | M22: =K22*L22 | N22: =$C$7 | O22: =M22*N22 | P22: deschide broșura
A23: 8 | B23: Sortare pe sită vibrantă cu aspirație | C23: Sit vibratoare cu aspirație pentru sortarea nucilor (300 kg/h) | D23: Sită 200 kg/h; separator miez 200 kg/h | E23: 300 | F23: Debit țintă ÷ capacitate unitară | G23: =ROUNDUP($C$10/E23,0) | H23: =G23*E23 | I23: =$C$10/H23 | J23: 3 | K23: =G23*J23 | L23: =$C$5 | M23: =K23*L23 | N23: =$C$7 | O23: =M23*N23 | P23: deschide broșura
A24: 9 | B24: Separare miez de coajă (coloană aspirație) | C24: Mașină pentru separarea miezului de coajă (300 kg/h) | D24: Separator 100 kg/h | E24: 300 | F24: Debit țintă ÷ capacitate unitară | G24: =ROUNDUP($C$10/E24,0) | H24: =G24*E24 | I24: =$C$10/H24 | J24: 1.5 | K24: =G24*J24 | L24: =$C$5 | M24: =K24*L24 | N24: =$C$7 | O24: =M24*N24 | P24: deschide broșura
A25: 10 | B25: Sortare optică miez | C25: Sortator optic cu bandă M600 | D25: Sortator optic 3S 400 kg/h; IR-63 200 kg/h | E25: 600 | F25: Debit țintă ÷ capacitate unitară | G25: =ROUNDUP($C$10/E25,0) | H25: =G25*E25 | I25: =$C$10/H25 | J25: 1.1 | K25: =G25*J25 | L25: =$C$5 | M25: =K25*L25 | N25: =$C$7 | O25: =M25*N25 | P25: deschide broșura | Q25: Precizie până la 99,5%. Broșura PDF lipsește pe site – de cerut.
A26: 11 | B26: Masă de inspecție finală | C26: Masă de inspecție cu bandă pe două niveluri | D26: Masă de inspecție simplă | E26: n/d | F26: Estimare | G26: =ROUNDUP($C$10/500,0) | H26: — | I26: — | J26: 1.1 | K26: =G26*J26 | L26: =$C$5 | M26: =K26*L26 | N26: =$C$7 | O26: =M26*N26 | P26: deschide broșura | Q26: Capacitate nedeclarată de producător – estimat 1 masă la 500 kg/h; de confirmat.
A27: 12 | B27: Transportoare elevatoare între utilaje | C27: Transportor elevatoare pentru nuci | D27: — | E27: n/d | F27: Estimare | G27: 4 | H27: — | I27: — | J27: 0.55 | K27: =G27*J27 | L27: =$C$5 | M27: =K27*L27 | N27: =$C$7 | O27: =M27*N27 | P27: deschide broșura | Q27: Capacitate nedeclarată – estimat 4 buc. (calibrare→spargere→sită→separator→sortare); de confirmat la proiectare.
B28: TOTAL LINIE | G28: =SUM(G16:G27) | K28: =SUM(K16:K27) | O28: =SUM(O16:O27)
A30: REZULTATE
A31: Debit linie – nucă uscată în coajă | C31: =C10 | D31: kg/h
A32: Nucă procesată pe zi | C32: =C10*C5 | D32: kg/zi
A33: Miez obținut pe oră | C33: =C10*C9 | D33: kg/h
A34: Miez obținut pe zi | C34: =C10*C5*C9 | D34: kg/zi
A35: Nucă procesată pe an | C35: =C11 | D35: t/an
A36: Miez obținut pe an | C36: =C11*C9 | D36: t/an
A37: Nucă de decojit și uscat pe zi în sezon | C37: =C11/C8 | D37: t/zi
A38: Număr total utilaje | C38: =G28 | D38: buc.
A39: Putere instalată totală | C39: =K28 | D39: kW
A40: Consum energie electrică estimat (100% sarcină) | C40: =O28 | D40: kWh/an
A41: din care uscare (sezon) | C41: =O17 | D41: kWh/an
A42: Debit maxim dacă se cumpără câte 1 buc./etapă | C42: =MIN(E19:E25) | D42: kg/h (limitat de spargere – 200 kg/h)
A43: Comparație: cea mai mare linie completă a producătorului | C43: 400 | D43: kg/h – „08. Linii complete de procesare\05...”

Sheet Preturi linie
A1: Linia ideală maximă – prețuri: magazin online Nut Technology vs. distribuitor România (TEHNO MSS SRL, Iași)
A2: Prețuri în EUR fără TVA. TEHNO MSS: ofertele nr. 82/16.04.2026 (200 kg/h și „400 kg/h”), valabile 60 de zile, deci expirate – de reconfirmat. Magazinul online shop.nuttechnology.com vinde doar spărgătoare casnice și unelte de recoltare (35–1.099 €), NU vinde utilaje industriale – pentru acestea producătorul dă preț doar la cerere (butonul „Request price”). Cantitățile sunt legate de foaia „Linie ideala” și se recalculează automat.
A4: Nr. | B4: Etapa / echipament din linia ideală | C4: Buc. linie ideală | D4: Magazin online – preț unitar | E4: Magazin online – total | F4: Echipament ofertat de TEHNO MSS | G4: Buc. necesare (varianta TEHNO MSS) | H4: TEHNO MSS – preț unitar | I4: TEHNO MSS – total | J4: Observații
A5: 1 | B5: Decojire coajă verde + spălare 1 t/h | C5: ='Linie ideala'!G16 | D5: nu se vinde online | E5: 0 | F5: Mașină industrială de curățat și spălat nuci 1 t/h | G5: ='Linie ideala'!G16 | H5: 29000 | I5: =G5*H5
A6: 2 | B6: Uscător nuci în coajă 4 t/zi | C6: ='Linie ideala'!G17 | D6: nu se vinde online | E6: 0 | F6: Uscător pentru nuci, alune, migdale 4 t/zi | G6: ='Linie ideala'!G17 | H6: 19200 | I6: =G6*H6 | J6: Ofertat „fără transportor”. Vezi analiza din 24.09: 14 kW pare insuficient pentru 4 t/șarjă.
A7: 3 | B7: Încărcare uscătoare (bandă 4 t/h) | C7: ='Linie ideala'!G18 | D7: nu se vinde online | E7: 0 | F7: Elevator Noria încărcare/descărcare 4 t/h (substitut) | G7: ='Linie ideala'!G18 | H7: 8600 | I7: =G7*H7 | J7: TEHNO MSS nu ofertează banda de alimentare; s-a luat elevatorul Noria. Un elevator ar putea deservi mai multe uscătoare – cantitate de optimizat.
A8: 4 | B8: Calibrator nuci 8 fracții 500 kg/h | C8: ='Linie ideala'!G19 | D8: nu se vinde online | E8: 0 | F8: Calibrator rotativ 4 fracții 300 kg/h | G8: =ROUNDUP('Linie ideala'!$C$10/300,0) | H8: 8600 | I8: =G8*H8 | J8: Model mai mic ofertat (300 kg/h) → sunt necesare mai multe bucăți.
A9: 5 | B9: Mașină de eliminat nuci goale 300 kg/h | C9: ='Linie ideala'!G20 | D9: nu se vinde online | E9: 0 | F9: — | G9: 0 | H9: neofertat | I9: 0 | J9: Neofertat – preț de cerut.
A10: 6 | B10: Spărgător cu aspirație 200 kg/h | C10: ='Linie ideala'!G21 | D10: nu se vinde online | E10: 0 | F10: Linie completă procesare nuci 200 kg/h (spărgător conic 200 kg/h + bandă + sită vibrantă cu aspirație + decorticator) | G10: =ROUNDUP('Linie ideala'!$C$10/200,0) | H10: 28600 | I10: =G10*H10 | J10: Pachetul acoperă pozițiile 6, 7 și 8. Varianta combinată (nuci+alune+migdale) costă 32.900 €/linie.
A11: 7 | B11: Spargere secundară 200 kg/h | C11: ='Linie ideala'!G22 | D11: nu se vinde online | E11: 0 | F11: inclus în linia completă (poz. 6) | G11: 0 | H11: neofertat | I11: 0
A12: 8 | B12: Sită vibrantă cu aspirație 300 kg/h | C12: ='Linie ideala'!G23 | D12: nu se vinde online | E12: 0 | F12: inclus în linia completă (poz. 6), 200 kg/h | G12: 0 | H12: neofertat | I12: 0
A13: 9 | B13: Separator miez de coajă 300 kg/h | C13: ='Linie ideala'!G24 | D13: nu se vinde online | E13: 0 | F13: — | G13: 0 | H13: neofertat | I13: 0 | J13: Neofertat.
A14: 10 | B14: Sortator optic miez M600 | C14: ='Linie ideala'!G25 | D14: nu se vinde online | E14: 0 | F14: — | G14: 0 | H14: neofertat | I14: 0 | J14: Neofertat. Estimare din analiza internă 24.09.2026: 35.000–60.000 €/buc.
A15: 11 | B15: Masă de inspecție finală | C15: ='Linie ideala'!G26 | D15: nu se vinde online | E15: 0 | F15: — | G15: 0 | H15: neofertat | I15: 0 | J15: Neofertată. Estimare analiză internă: 3.000–6.000 €/buc.
A16: 12 | B16: Transportoare elevatoare | C16: ='Linie ideala'!G27 | D16: nu se vinde online | E16: 0 | F16: parțial incluse (1 bandă în fiecare linie completă) | G16: 0 | H16: neofertat | I16: 0
B17: TOTAL echipamente fără TVA | D17: n/a – fără prețuri industriale online | E17: =SUM(E5:E16) | I17: =SUM(I5:I16) | J17: Totalul TEHNO MSS acoperă doar pozițiile ofertate. Lipsesc: eliminare nuci goale, separator miez, sortator optic, mese de inspecție, tablou electric/PLC, montaj.
B18: TVA 21% | E18: =E17*0.21 | I18: =I17*0.21
B19: TOTAL cu TVA | E19: =E17+E18 | I19: =I17+I18
B20: Număr utilaje | E20: =SUM(C5:C16) | I20: =SUM(G5:G16)

Sheet Linie 3 spargatoare
A1: Linie cu 3 spărgătoare (2 în linia automatizată + 1 separat) – capacitate maximă cu număr minim de utilaje (Nut Technology)
A2: Principiu: pe fiecare etapă se alege cel mai mare utilaj din gama producătorului, astfel încât o singură bucată să acopere debitul liniei. Spargere: 3 × 200 = 600 kg/h; gâtuirea devine sita vibrantă a liniei și calibratorul (500 kg/h) → debit real 500 kg/h. Prețuri în EUR fără TVA: cele marcate „Tehno MSS” sunt din oferta 82/16.04.2026, restul sunt estimări orientative, de confirmat prin ofertă.
A4: Ore de lucru pe zi | C4: 8
A5: Zile de procesare pe an | C5: 250
A6: Randament miez | C6: 0.45
A8: Nr. | B8: Etapa | C8: Utilaj ales | D8: Buc. | E8: Capacitate / buc. | F8: Grad încărcare la 500 kg/h | G8: Putere kW / buc. | H8: Putere totală kW | I8: Preț min (€) | J8: Preț max (€) | K8: Sursa preț | L8: Broșura | M8: De ce e suficient 1 buc. / observații
A9: 1 | B9: Spălare + decojire coajă verde | C9: Mașină industrială de decojire și spălare 1 t/h | D9: 1 | E9: 1.000 kg/h | F9: sezon | G9: 3.7 | H9: =D9*G9 | I9: =D9*29000 | J9: =D9*29000 | K9: Tehno MSS | L9: deschide | M9: 1 t/h > 500 kg/h. Doar în sezon.
A10: 2 | B10: Alimentare mașină de spălat | C10: Bandă transportoare de alimentare 4 t/h | D10: 1 | E10: 4 t/h | F10: — | G10: 0.55 | H10: =D10*G10 | I10: =D10*2500 | J10: =D10*4500 | K10: estimare | L10: deschide | M10: Cerută în „Customer request”.
A11: 3 | B11: Încărcare/descărcare uscătoare | C11: Elevator Noria 4 t/h | D11: 1 | E11: 4 t/h | F11: — | G11: 1.5 | H11: =D11*G11 | I11: =D11*8600 | J11: =D11*8600 | K11: Tehno MSS | L11: deschide | M11: Un elevator încarcă o șarjă de 4 t în circa 1 h – deservește ambele uscătoare. Putere nedeclarată (estimat 1,5 kW).
A12: 4 | B12: Uscare | C12: Uscător nuci în coajă 4 t/24 h | D12: 2 | E12: 4 t/zi | F12: sezon | G12: 14 | H12: =D12*G12 | I12: =D12*19200 | J12: =D12*19200 | K12: Tehno MSS | L12: deschide | M12: 2 buc. = 360 t/sezon (45 zile). Restul de circa 640 t/an se cumpără uscat. Pentru uscarea integrală a 1.000 t/an: 6 buc. Bilanțul termic (14 kW) trebuie confirmat.
A13: 5 | B13: Calibrare | C13: Calibrator nuci 8 fracții 500 kg/h (cu bandă de alimentare inclusă) | D13: 1 | E13: 500 kg/h | F13: =500/500 | G13: 2.95 | H13: =D13*G13 | I13: =D13*12000 | J13: =D13*18000 | K13: estimare | L13: deschide | M13: Înlocuiește cele 2 calibratoare de 300 kg/h din ofertă. Are banda de alimentare integrată (0,75 kW).
A14: 6 | B14: Spargere + aspirație + transport + respargere + sită | C14: Linie automatizată de procesare nuci 400 kg/h (2 spărgătoare conice Etalon, decorticator mărit, sită vibrantă cu aspirație 500 kg/h, panou unic) | D14: 1 | E14: 400 kg/h spargere / 500 kg/h sită | F14: =500/500 | G14: 12 | H14: =D14*G14 | I14: =D14*50000 | J14: =D14*65000 | K14: estimare (2 × linia de 200 kg/h Tehno MSS = 57.200) | L14: deschide | M14: UN SINGUR utilaj înlocuiește 2 linii de 200 kg/h. Aspirație pe fiecare fracție la sită → separatorul de miez separat nu mai e necesar. Putere nedeclarată (estimat 12 kW).
A15: 7 | B15: Spargere – al 3-lea spărgător | C15: Spărgător industrial de nuci cu coloană de aspirație integrată 200 kg/h | D15: 1 | E15: 200 kg/h | F15: =100/200 | G15: 2.05 | H15: =D15*G15 | I15: =D15*0 | J15: =D15*0 | K15: de cerut | L15: deschide | M15: Lucrează în paralel cu cele 2 spărgătoare din linie și descarcă în decorticatorul/sita liniei. Spargere totală 600 kg/h; la 500 kg/h debit real e încărcat circa 50% – rezervă și redundanță la defectarea unui spărgător.
A16: 8 | B16: Transport între etape | C16: Transportor elevator pentru nuci | D16: 2 | E16: — | F16: — | G16: 0.55 | H16: =D16*G16 | I16: =D16*1500 | J16: =D16*3000 | K16: estimare | L16: deschide | M16: Calibrator → buncăr linie; linie → sortator optic.
A17: 9 | B17: Sortare optică miez | C17: Sortator optic cu bandă M600 | D17: 1 | E17: 600 kg/h | F17: =500/600 | G17: 1.1 | H17: =D17*G17 | I17: =D17*40000 | J17: =D17*70000 | K17: estimare | L17: deschide | M17: 600 kg/h – rezervă de 50%. Scoate resturile de coajă și miezul închis la culoare; reduce sortarea manuală. Alternativă mai ieftină: 3S (400 kg/h, 100% încărcat). Broșura PDF – de cerut.
A18: 10 | B18: Inspecție finală | C18: Masă de inspecție cu bandă pe două niveluri | D18: 1 | E18: — | F18: — | G18: 1.1 | H18: =D18*G18 | I18: =D18*3000 | J18: =D18*6000 | K18: estimare | L18: deschide | M18: Două niveluri = două fluxuri pe aceeași masă.
B19: TOTAL utilaje și investiție (fără TVA) | D19: =SUM(D9:D18) | H19: =SUM(H9:H18) | I19: =SUM(I9:I18) | J19: =SUM(J9:J18)
B20: TOTAL fără sortator optic | D20: =D19-1 | H20: =H19-1.1 | I20: =I19-I17 | J20: =J19-J17
B21: TOTAL cu TVA 21% | I21: =I19*1.21 | J21: =J19*1.21
A23: PRODUCȚIE
A24: Debit linie (gâtuire: sita liniei și calibratorul, 500 kg/h) | C24: 500 | D24: kg/h
A25: Nucă procesată pe zi | C25: =500*C4 | D25: kg/zi
A26: Miez pe zi | C26: =500*C4*C6 | D26: kg/zi
A27: Nucă procesată pe an | C27: =500*C4*C5/1000 | D27: t/an
A28: Miez pe an | C28: =500*C4*C5*C6/1000 | D28: t/an
A29: Nucă uscată în sezon cu 2 uscătoare | C29: =2*4*45 | D29: t/sezon
A30: Nucă de cumpărat deja uscată | C30: =MAX(0,500*C4*C5/1000-2*4*45) | D30: t/an
A32: CE S-A ELIMINAT FAȚĂ DE VARIANTA TEHNO MSS + EXTINDERE LA 400 kg/h (22 utilaje → 12)
A33: • 2 linii de 200 kg/h → 1 linie automatizată de 400 kg/h (un singur panou de comandă, un singur operator).
A34: • 2 calibratoare 4 fracții de 300 kg/h → 1 calibrator 8 fracții de 500 kg/h, cu bandă de alimentare integrată (8 fracții = spargere mai bună, mai mult miez întreg).
A35: • 2 separatoare de miez → 0: sita de 500 kg/h din linia de 400 are coloană de aspirație pe fiecare fracție, iar sortatorul optic scoate resturile de coajă.
A36: • 2 mașini de sortat nuci goale → 0 (opțional): nucile goale sunt eliminate de aspirația de după spargere și de sortatorul optic. Se recomandă doar dacă se cumpără nucă de la mulți furnizori – atunci 2 buc. × 300 kg/h (+4,5 kW fiecare).
A37: • 2 mese de inspecție → 1 masă pe două niveluri; transportoare 4 → 2; benzi uscător 3 → 1 elevator Noria pentru ambele uscătoare.
A38: • Decojitorul de alune din ofertă nu e inclus – se adaugă doar dacă se procesează și alune (4.300 €).

Sheet Brosuri unice
A1: Fișier broșură pe site | B1: Link direct | C1: Folosit pentru (echipamente)
A2: 36.png | B2: https://nuttechnology.com/wp-content/uploads/36.png | C2: Sortator optic 3S
A3: AUTOMATED-INDUSTRIAL-WALNUT-PROCESSING-LINE-200-KG_H.pdf | B3: https://nuttechnology.com/wp-content/uploads/AUTOMATED-INDUSTRIAL-WALNUT-PROCESSING-LINE-200-KG_H.pdf | C3: Linie industrială automatizată pentru procesarea nucilor (200 kg/h)
A4: AUTOMATED-INDUSTRIAL-WALNUT-PROCESSING-LINE-400.pdf | B4: https://nuttechnology.com/wp-content/uploads/AUTOMATED-INDUSTRIAL-WALNUT-PROCESSING-LINE-400.pdf | C4: Linie industrială automatizată de procesare a nucilor, până la 400 kg/h
A5: Belt-inspection-table_compressed.pdf | B5: https://nuttechnology.com/wp-content/uploads/Belt-inspection-table_compressed.pdf | C5: Masă de inspecție cu bandă
