Workbook

Sheet START
A1: DRACULA BOOK — 100 TITLURI / 300 EDIȚII
A2: Actualizat la | B2: 46288 | C2: Plan condiționat de capacitate și buget; nu dovadă de publicare.
A3: Titluri distincte planificate | B3: =COUNTA(Catalog_100!A2:A101) -> 100 | C3: 17 proiecte existente + 83 concepte noi.
A4: Manuscrise candidate existente | B4: =COUNTIF(Catalog_100!F2:F101,"Fond") -> 17 | C4: 14 EN + 3 RO; Signal incomplet.
A5: Titluri noi de scris | B5: =COUNTIF(Catalog_100!F2:F101,"Nou") -> 83 | C5: Titlurile și premisele sunt propuse, nu manuscrise finalizate.
A6: Ediții lingvistice planificate | B6: =COUNTA(Editii_300!A2:A301) -> 300 | C6: 100 EN + 100 RO + 100 DE.
A7: Ediții publicate cu dovezi complete | B7: =SUM(Editii_300!X2:X301) -> 0 | C7: Stare Publicat + aprobator + dată + URL + checksum + drepturi confirmate.
A8: Titluri încheiate în toate 3 limbile | B8: =SUM(Catalog_100!T2:T101) -> 0 | C8: Niciun titlu nu este marcat final doar pentru existența unui fișier.
A9: Cuvinte master planificate | B9: =SUM(Catalog_100!I2:I101) -> 5419000 | C9: Lungimi de lucru; nu cuvinte deja aprobate.
A10: Echivalent cuvinte de tradus | B10: =B9*2 -> 10838000 | C10: 200 operațiuni; 3 RO→EN, 97 EN→RO, 100 spre DE.
A11: Buget bază cu rezervă EUR | B11: =Buget!G18 -> 1532203.2 | C11: Ipoteze de externalizare, nu ofertă; exclude taxele aplicabile.
A12: Necesar echivalent execuție | B12: =Capacitate!H11 -> 203 | C12: Adăugați coordonare/design; nu este personal existent.
A14: CUM SE FOLOSEȘTE
A15: 1. Audit_17 | B15: Verificare | C15: Confirmați masterul, autorul, titlul, limba, drepturile și distinctivitatea.
A16: 2. Catalog_100 | B16: Plan editorial | C16: Desemnați autor/editor; detaliați fiecare premisă într-un brief de 2–4 pagini.
A17: 3. Editii_300 | B17: Progres real | C17: Actualizați starea și aprobările. Publicat fără probe nu crește indicatorul verificat.
A18: 4. Capacitate / Buget | B18: Ipoteze editabile | C18: Celulele albastre sunt ipoteze; înlocuiți cu timpi și oferte măsurate.
A19: 5. Scenarii | B19: Nu prognoze | C19: Modelul de abonament este context comercial, nu modificare a site-ului.
A20: 6. Surse | B20: Trasabilitate | C20: Anii datelor diferă; nu adunați piețe cu metodologii diferite.
A21: 7. Calendar | B21: Scenariu accelerat | C21: Comparați săptămânal țintele cu realizatul; nu schimbați starea pentru a bifa data.
A23: LIMITĂ DE AUDIT | B23: Important | C23: Inventar și structură plus eșantioane, nu lectură literară integrală a 17 manuscrise.
A24: FIȘIERE ORIGINALE | B24: Nemodificate | C24: Acest registru nu mută și nu rescrie cărțile și nu modifică site-ul.
A25: INFORMAȚII LIPSĂ | B25: De furnizat | C25: Buget aprobat, echipă disponibilă, vânzări actuale, dovezi ISBN/ASIN/linkuri și drepturi.

Sheet Catalog_100
A1: WorkID | B1: Colecție | C1: Saga | D1: Volum | E1: Titlu de lucru / existent | F1: Bază | G1: Sursă | H1: Stare inițială | I1: Țintă cuvinte | J1: Master EN țintă | K1: Traduceri țintă | L1: QA țintă | M1: Lansare trilingvă țintă | N1: Lot | O1: Responsabil | P1: Gen / format | Q1: Premisă de lucru | R1: Observații | S1: Ediții verificate | T1: Titlu trilingv realizat
A2: DB-001 | B2: NOIR | C2: Cronicile Transilvaniei | D2: 1 | E2: Umbra Trandafirului Negru | F2: Fond | G2: RO | H2: Manuscris candidat — nevalidat editorial | I2: 60000 | J2: 46298 | K2: 46301 | L2: 46303 | M2: 46305 | N2: PILOT | O2: De contractat / desemnat | P2: Roman istoric-gotic | Q2: Vlad, Bran și o conspirație; de stabilit cronologia istoric-fantastică. | R2: Materiale de lucru și profiluri înaintea romanului; cronologie de corelat cu site-ul. | S2: =COUNTIFS(Editii_300!$B$2:$B$301,A2,Editii_300!$X$2:$X$301,1) -> 0 | T2: =IF(S2=3,1,0) -> 0
A3: DB-002 | B3: NOIR | C3: Cronicile Transilvaniei | D3: 2 | E3: Marienburg: Sigiliul Fecioarei | F3: Fond | G3: RO | H3: Manuscris candidat — nevalidat editorial | I3: 70000 | J3: 46305 | K3: 46315 | L3: 46317 | M3: 46319 | N3: FOND EXISTENT | O3: De contractat / desemnat | P3: Roman istoric-gotic | Q3: Anchetă la Feldioara; legătura dintre două epoci. | R3: Circa 76,8k cuvinte brute, nu 85–95k confirmate; marcaje și epoci de verificat. | S3: =COUNTIFS(Editii_300!$B$2:$B$301,A3,Editii_300!$X$2:$X$301,1) -> 0 | T3: =IF(S3=3,1,0) -> 0
A4: DB-003 | B4: NOIR | C4: Cronicile Transilvaniei | D4: 3 | E4: Sânge și Sare la Schäßburg | F4: Fond | G4: RO | H4: Manuscris candidat — nevalidat editorial | I4: 80000 | J4: 46305 | K4: 46315 | L4: 46317 | M4: 46319 | N4: FOND EXISTENT | O4: De contractat / desemnat | P4: Roman istoric-gotic | Q4: Titlu de reconciliat cu CIVITAS SEX – Legământul de Sare. | R4: Titlul interior diferă de copertă/site; prefată de proces AI și note de eliminat. | S4: =COUNTIFS(Editii_300!$B$2:$B$301,A4,Editii_300!$X$2:$X$301,1) -> 0 | T4: =IF(S4=3,1,0) -> 0
A5: DB-004 | B5: NOIR | C5: Cronicile Transilvaniei | D5: 4 | E5: The Bellmaker of Brașov | F5: Nou | G5: EN | H5: Concept propus; nescris | I5: 60000 | J5: 46318 | K5: 46336 | L5: 46338 | M5: 46340 | N5: LOT C | O5: De contractat / desemnat | P5: Roman istoric-gotic | Q5: Un clopot nou anunță crime înainte să fie comise. | S5: =COUNTIFS(Editii_300!$B$2:$B$301,A5,Editii_300!$X$2:$X$301,1) -> 0 | T5: =IF(S5=3,1,0) -> 0
A6: DB-005 | B6: NOIR | C6: Cronicile Transilvaniei | D6: 5 | E6: The Sibiu Testament | F6: Nou | G6: EN | H6: Concept propus; nescris | I6: 60000 | J6: 46318 | K6: 46336 | L6: 46338 | M6: 46340 | N6: LOT C | O6: De contractat / desemnat | P6: Roman istoric-gotic | Q6: O moștenire schimbă mâinile de fiecare dată când moare un martor. | S6: =COUNTIFS(Editii_300!$B$2:$B$301,A6,Editii_300!$X$2:$X$301,1) -> 0 | T6: =IF(S6=3,1,0) -> 0
A7: DB-006 | B7: NOIR | C7: Cronicile Transilvaniei | D7: 6 | E7: The Bistrița Bride | F7: Nou | G7: EN | H7: Concept propus; nescris | I7: 60000 | J7: 46318 | K7: 46336 | L7: 46338 | M7: 46340 | N7: LOT C | O7: De contractat / desemnat | P7: Roman istoric-gotic | Q7: O nuntă politică ascunde dispariția miresei din registrul parohial. | S7: =COUNTIFS(Editii_300!$B$2:$B$301,A7,Editii_300!$X$2:$X$301,1) -> 0 | T7: =IF(S7=3,1,0) -> 0
A8: DB-007 | B8: NOIR | C8: Cronicile Transilvaniei | D8: 7 | E8: The Locksmith of Sighișoara | F8: Nou | G8: EN | H8: Concept propus; nescris | I8: 60000 | J8: 46318 | K8: 46336 | L8: 46338 | M8: 46340 | N8: LOT C | O8: De contractat / desemnat | P8: Roman istoric-gotic | Q8: Un meșter recunoaște propria cheie într-o cameră sigilată. | S8: =COUNTIFS(Editii_300!$B$2:$B$301,A8,Editii_300!$X$2:$X$301,1) -> 0 | T8: =IF(S8=3,1,0) -> 0
A9: DB-008 | B9: NOIR | C9: Cronicile Transilvaniei | D9: 8 | E9: The Alba Iulia Cipher | F9: Nou | G9: EN | H9: Concept propus; nescris | I9: 60000 | J9: 46318 | K9: 46336 | L9: 46338 | M9: 46340 | N9: LOT C | O9: De contractat / desemnat | P9: Roman istoric-gotic | Q9: O traducătoare descoperă un verdict ascuns într-o cronică. | S9: =COUNTIFS(Editii_300!$B$2:$B$301,A9,Editii_300!$X$2:$X$301,1) -> 0 | T9: =IF(S9=3,1,0) -> 0
A10: DB-009 | B10: NOIR | C10: Cronicile Transilvaniei | D10: 9 | E10: The Winter Court of Bran | F10: Nou | G10: EN | H10: Concept propus; nescris | I10: 60000 | J10: 46318 | K10: 46336 | L10: 46338 | M10: 46340 | N10: LOT C | O10: De contractat / desemnat | P10: Roman istoric-gotic | Q10: Un asediu de iarnă transformă aliații în suspecți. | S10: =COUNTIFS(Editii_300!$B$2:$B$301,A10,Editii_300!$X$2:$X$301,1) -> 0 | T10: =IF(S10=3,1,0) -> 0
A11: DB-010 | B11: NOIR | C11: Cronicile Transilvaniei | D11: 10 | E11: The Last Black Rose | F11: Nou | G11: EN | H11: Concept propus; nescris | I11: 60000 | J11: 46318 | K11: 46336 | L11: 46338 | M11: 46340 | N11: LOT C | O11: De contractat / desemnat | P11: Roman istoric-gotic | Q11: Ultimul caz închide arcul conspirației fără a repeta primul volum. | S11: =COUNTIFS(Editii_300!$B$2:$B$301,A11,Editii_300!$X$2:$X$301,1) -> 0 | T11: =IF(S11=3,1,0) -> 0
A12: DB-011 | B12: NOIR | C12: Carpathian Cold Cases | D12: 1 | E12: The Witness Beneath the Ice | F12: Nou | G12: EN | H12: Concept propus; nescris | I12: 55000 | J12: 46311 | K12: 46329 | L12: 46331 | M12: 46333 | N12: LOT B | O12: De contractat / desemnat | P12: Thriller contemporan | Q12: Topirea unui lac readuce o dispariție și un martor mincinos. | S12: =COUNTIFS(Editii_300!$B$2:$B$301,A12,Editii_300!$X$2:$X$301,1) -> 0 | T12: =IF(S12=3,1,0) -> 0
A13: DB-012 | B13: NOIR | C13: Carpathian Cold Cases | D13: 2 | E13: The Missing Carriage | F13: Nou | G13: EN | H13: Concept propus; nescris | I13: 55000 | J13: 46311 | K13: 46329 | L13: 46331 | M13: 46333 | N13: LOT B | O13: De contractat / desemnat | P13: Thriller contemporan | Q13: O înregistrare feroviară dovedește existența unui vagon dispărut. | S13: =COUNTIFS(Editii_300!$B$2:$B$301,A13,Editii_300!$X$2:$X$301,1) -> 0 | T13: =IF(S13=3,1,0) -> 0
A14: DB-013 | B14: NOIR | C14: Carpathian Cold Cases | D14: 3 | E14: The Village That Forgot Her | F14: Nou | G14: EN | H14: Concept propus; nescris | I14: 55000 | J14: 46311 | K14: 46329 | L14: 46331 | M14: 46333 | N14: LOT B | O14: De contractat / desemnat | P14: Thriller contemporan | Q14: O arhivistă găsește aceeași femeie ștearsă din toate fotografiile. | S14: =COUNTIFS(Editii_300!$B$2:$B$301,A14,Editii_300!$X$2:$X$301,1) -> 0 | T14: =IF(S14=3,1,0) -> 0
A15: DB-014 | B15: NOIR | C15: Carpathian Cold Cases | D15: 4 | E15: The Funeral Guest | F15: Nou | G15: EN | H15: Concept propus; nescris | I15: 55000 | J15: 46311 | K15: 46329 | L15: 46331 | M15: 46333 | N15: LOT B | O15: De contractat / desemnat | P15: Thriller contemporan | Q15: Un necunoscut lasă o probă la înmormântarea unei anchetatoare. | S15: =COUNTIFS(Editii_300!$B$2:$B$301,A15,Editii_300!$X$2:$X$301,1) -> 0 | T15: =IF(S15=3,1,0) -> 0
A16: DB-015 | B16: NOIR | C16: Carpathian Cold Cases | D16: 5 | E16: The Quarry Silence | F16: Nou | G16: EN | H16: Concept propus; nescris | I16: 55000 | J16: 46311 | K16: 46329 | L16: 46331 | M16: 46333 | N16: LOT B | O16: De contractat / desemnat | P16: Thriller contemporan | Q16: O carieră dezafectată amenință pactul unui oraș prosper. | S16: =COUNTIFS(Editii_300!$B$2:$B$301,A16,Editii_300!$X$2:$X$301,1) -> 0 | T16: =IF(S16=3,1,0) -> 0
... A36: DB-035 | B36: NOIR | C36: The Borderland Files | D36: 5 | E36: The Bridge at First Snow | F36: Nou | G36: EN | H36: Concept propus; nescris | I36: 35000 | J36: 46304 | K36: 46322 | L36: 46324 | M36: 46326 | N36: LOT A | O36: De contractat / desemnat | P36: Roman scurt de mister | Q36: O punte izolată adună trei versiuni incompatibile ale aceleiași nopți. | S36: =COUNTIFS(Editii_300!$B$2:$B$301,A36,Editii_300!$X$2:$X$301,1) -> 0 | T36: =IF(S36=3,1,0) -> 0
A37: DB-036 | B37: AMORIS | C37: Alex Damian | D37: 1 | E37: Beneath the Skin of the Sea | F37: Fond | G37: EN | H37: Manuscris candidat — nevalidat editorial | I37: 80000 | J37: 46298 | K37: 46301 | L37: 46303 | M37: 46305 | N37: PILOT | O37: De contractat / desemnat | P37: Romance de aventură | Q37: Alex și Elena; epavă grecească, vulnerabilitate și reconstrucție. | R37: Raportul intern de 9,87/10 nu dovedește recenzie independentă sau publicare. | S37: =COUNTIFS(Editii_300!$B$2:$B$301,A37,Editii_300!$X$2:$X$301,1) -> 0 | T37: =IF(S37=3,1,0) -> 0
A38: DB-037 | B38: AMORIS | C38: Alex Damian | D38: 2 | E38: Shadows in the Port | F38: Fond | G38: EN | H38: Manuscris candidat — nevalidat editorial | I38: 90000 | J38: 46305 | K38: 46315 | L38: 46317 | M38: 46319 | N38: FOND EXISTENT | O38: De contractat / desemnat | P38: Romance de aventură | Q38: De verificat distinctivitatea față de Beneath; rescris ca sequel dacă este variantă. | R38: Alex/Elena și început apropiat de Beneath; verificare sequel vs rescriere; heading 5 neidentificat. | S38: =COUNTIFS(Editii_300!$B$2:$B$301,A38,Editii_300!$X$2:$X$301,1) -> 0 | T38: =IF(S38=3,1,0) -> 0
A39: DB-038 | B39: AMORIS | C39: Alex Damian | D39: 3 | E39: The Last Sunset in Santorini | F39: Nou | G39: EN | H39: Concept propus; nescris | I39: 60000 | J39: 46318 | K39: 46336 | L39: 46338 | M39: 46340 | N39: LOT C | O39: De contractat / desemnat | P39: Romance de aventură | Q39: Un proiect de salvare amenință promisiunea făcută pe uscat. | S39: =COUNTIFS(Editii_300!$B$2:$B$301,A39,Editii_300!$X$2:$X$301,1) -> 0 | T39: =IF(S39=3,1,0) -> 0
A40: DB-039 | B40: AMORIS | C40: Alex Damian | D40: 4 | E40: Breath of the Deep | F40: Nou | G40: EN | H40: Concept propus; nescris | I40: 60000 | J40: 46318 | K40: 46336 | L40: 46338 | M40: 46340 | N40: LOT C | O40: De contractat / desemnat | P40: Romance de aventură | Q40: O epavă readuce o datorie din trecutul naval. | S40: =COUNTIFS(Editii_300!$B$2:$B$301,A40,Editii_300!$X$2:$X$301,1) -> 0 | T40: =IF(S40=3,1,0) -> 0
A41: DB-040 | B41: AMORIS | C41: Alex Damian | D41: 5 | E41: The Woman in the Blue Light | F41: Nou | G41: EN | H41: Concept propus; nescris | I41: 60000 | J41: 46318 | K41: 46336 | L41: 46338 | M41: 46340 | N41: LOT C | O41: De contractat / desemnat | P41: Romance de aventură | Q41: O dispariție obligă o jurnalistă și un scafandru să coopereze. | S41: =COUNTIFS(Editii_300!$B$2:$B$301,A41,Editii_300!$X$2:$X$301,1) -> 0 | T41: =IF(S41=3,1,0) -> 0
A42: DB-041 | B42: AMORIS | C42: Alex Damian | D42: 6 | E42: The Island Without Names | F42: Nou | G42: EN | H42: Concept propus; nescris | I42: 60000 | J42: 46318 | K42: 46336 | L42: 46338 | M42: 46340 | N42: LOT C | O42: De contractat / desemnat | P42: Romance de aventură | Q42: O furtună testează încrederea unei echipe izolate. | S42: =COUNTIFS(Editii_300!$B$2:$B$301,A42,Editii_300!$X$2:$X$301,1) -> 0 | T42: =IF(S42=3,1,0) -> 0
A43: DB-042 | B43: AMORIS | C43: Alex Damian | D43: 7 | E43: Coral Hearts | F43: Nou | G43: EN | H43: Concept propus; nescris | I43: 60000 | J43: 46318 | K43: 46336 | L43: 46338 | M43: 46340 | N43: LOT C | O43: De contractat / desemnat | P43: Romance de aventură | Q43: O expediție ecologică pune iubirea și ambiția în conflict. | S43: =COUNTIFS(Editii_300!$B$2:$B$301,A43,Editii_300!$X$2:$X$301,1) -> 0 | T43: =IF(S43=3,1,0) -> 0
A44: DB-043 | B44: AMORIS | C44: Alex Damian | D44: 8 | E44: Beneath the Salt Stars | F44: Nou | G44: EN | H44: Concept propus; nescris | I44: 60000 | J44: 46318 | K44: 46336 | L44: 46338 | M44: 46340 | N44: LOT C | O44: De contractat / desemnat | P44: Romance de aventură | Q44: O iubire veche cere un adevăr pe care nimeni nu l-a spus. | S44: =COUNTIFS(Editii_300!$B$2:$B$301,A44,Editii_300!$X$2:$X$301,1) -> 0 | T44: =IF(S44=3,1,0) -> 0
A45: DB-044 | B45: AMORIS | C45: Alex Damian | D45: 9 | E45: Tidebound | F45: Nou | G45: EN | H45: Concept propus; nescris | I45: 60000 | J45: 46318 | K45: 46336 | L45: 46338 | M45: 46340 | N45: LOT C | O45: De contractat / desemnat | P45: Romance de aventură | Q45: Salvarea unui vas schimbă planul unei vieți împreună. | S45: =COUNTIFS(Editii_300!$B$2:$B$301,A45,Editii_300!$X$2:$X$301,1) -> 0 | T45: =IF(S45=3,1,0) -> 0
A46: DB-045 | B46: AMORIS | C46: Alex Damian | D46: 10 | E46: The Echo Below | F46: Nou | G46: EN | H46: Concept propus; nescris | I46: 60000 | J46: 46318 | K46: 46336 | L46: 46338 | M46: 46340 | N46: LOT C | O46: De contractat / desemnat | P46: Romance de aventură | Q46: Un secret de familie încheie arcul lui Alex printr-o alegere ireversibilă. | S46: =COUNTIFS(Editii_300!$B$2:$B$301,A46,Editii_300!$X$2:$X$301,1) -> 0 | T46: =IF(S46=3,1,0) -> 0
A47: DB-046 | B47: AMORIS | C47: Isabella Morgan / Rue des Âmes | D47: 1 | E47: Hotelul din Rue des Âmes | F47: Fond | G47: EN | H47: Manuscris candidat — nevalidat editorial | I47: 85000 | J47: 46298 | K47: 46301 | L47: 46303 | M47: 46305 | N47: PILOT | O47: De contractat / desemnat | P47: Romance contemporan | Q47: Manuscris EN; Isabella și scrisorile unui hotel din Paris. | R47: Folderul V1 conține copie identică a Aurora 1; heading CHAPTER 11 neidentificat; nu se deduce automat lipsa prozei. | S47: =COUNTIFS(Editii_300!$B$2:$B$301,A47,Editii_300!$X$2:$X$301,1) -> 0 | T47: =IF(S47=3,1,0) -> 0
A48: DB-047 | B48: AMORIS | C48: Isabella Morgan / Rue des Âmes | D48: 2 | E48: The Magenta Letters | F48: Nou | G48: EN | H48: Concept propus; nescris | I48: 60000 | J48: 46325 | K48: 46343 | L48: 46345 | M48: 46347 | N48: LOT D | O48: De contractat / desemnat | P48: Romance contemporan | Q48: Promisiunea din finalul existent: povestea lui Margaux, în universul comun. | S48: =COUNTIFS(Editii_300!$B$2:$B$301,A48,Editii_300!$X$2:$X$301,1) -> 0 | T48: =IF(S48=3,1,0) -> 0
A49: DB-048 | B49: AMORIS | C49: Isabella Morgan / Rue des Âmes | D49: 3 | E49: Coffee at the Edge of the World | F49: Nou | G49: EN | H49: Concept propus; nescris | I49: 60000 | J49: 46325 | K49: 46343 | L49: 46345 | M49: 46347 | N49: LOT D | O49: De contractat / desemnat | P49: Romance contemporan | Q49: Lisabona; o întâlnire schimbă definiția succesului. | S49: =COUNTIFS(Editii_300!$B$2:$B$301,A49,Editii_300!$X$2:$X$301,1) -> 0 | T49: =IF(S49=3,1,0) -> 0
A50: DB-049 | B50: AMORIS | C50: Isabella Morgan / Rue des Âmes | D50: 4 | E50: Under the Tokyo Sky | F50: Nou | G50: EN | H50: Concept propus; nescris | I50: 60000 | J50: 46325 | K50: 46343 | L50: 46345 | M50: 46347 | N50: LOT D | O50: De contractat / desemnat | P50: Romance contemporan | Q50: Doi profesioniști aleg între reputație și o relație imposibil de ascuns. | S50: =COUNTIFS(Editii_300!$B$2:$B$301,A50,Editii_300!$X$2:$X$301,1) -> 0 | T50: =IF(S50=3,1,0) -> 0
A51: DB-050 | B51: AMORIS | C51: Isabella Morgan / Rue des Âmes | D51: 5 | E51: Vienna After Hours | F51: Nou | G51: EN | H51: Concept propus; nescris | I51: 60000 | J51: 46325 | K51: 46343 | L51: 46345 | M51: 46347 | N51: LOT D | O51: De contractat / desemnat | P51: Romance contemporan | Q51: Un concert ratat deschide o a doua șansă. | S51: =COUNTIFS(Editii_300!$B$2:$B$301,A51,Editii_300!$X$2:$X$301,1) -> 0 | T51: =IF(S51=3,1,0) -> 0
A52: DB-051 | B52: AMORIS | C52: Isabella Morgan / Rue des Âmes | D52: 6 | E52: The Woman on Charles Bridge | F52: Nou | G52: EN | H52: Concept propus; nescris | I52: 60000 | J52: 46325 | K52: 46343 | L52: 46345 | M52: 46347 | N52: LOT D | O52: De contractat / desemnat | P52: Romance contemporan | Q52: O conferință din Praga readuce un secret de familie. | S52: =COUNTIFS(Editii_300!$B$2:$B$301,A52,Editii_300!$X$2:$X$301,1) -> 0 | T52: =IF(S52=3,1,0) -> 0
A53: DB-052 | B53: AMORIS | C53: Isabella Morgan / Rue des Âmes | D53: 7 | E53: The Marrakech Letter | F53: Nou | G53: EN | H53: Concept propus; nescris | I53: 60000 | J53: 46325 | K53: 46343 | L53: 46345 | M53: 46347 | N53: LOT D | O53: De contractat / desemnat | P53: Romance contemporan | Q53: O scrisoare schimbă cine are dreptul să spună o poveste. | S53: =COUNTIFS(Editii_300!$B$2:$B$301,A53,Editii_300!$X$2:$X$301,1) -> 0 | T53: =IF(S53=3,1,0) -> 0
A54: DB-053 | B54: AMORIS | C54: Isabella Morgan / Rue des Âmes | D54: 8 | E54: Flight Over Rome | F54: Nou | G54: EN | H54: Concept propus; nescris | I54: 60000 | J54: 46325 | K54: 46343 | L54: 46345 | M54: 46347 | N54: LOT D | O54: De contractat / desemnat | P54: Romance contemporan | Q54: Un zbor anulat obligă doi rivali să împartă o călătorie. | S54: =COUNTIFS(Editii_300!$B$2:$B$301,A54,Editii_300!$X$2:$X$301,1) -> 0 | T54: =IF(S54=3,1,0) -> 0
A55: DB-054 | B55: AMORIS | C55: Isabella Morgan / Rue des Âmes | D55: 9 | E55: Shadows of Buenos Aires | F55: Nou | G55: EN | H55: Concept propus; nescris | I55: 60000 | J55: 46325 | K55: 46343 | L55: 46345 | M55: 46347 | N55: LOT D | O55: De contractat / desemnat | P55: Romance contemporan | Q55: Dans, încredere și o alegere între plecare și apartenență. | S55: =COUNTIFS(Editii_300!$B$2:$B$301,A55,Editii_300!$X$2:$X$301,1) -> 0 | T55: =IF(S55=3,1,0) -> 0
A56: DB-055 | B56: AMORIS | C56: Isabella Morgan / Rue des Âmes | D56: 10 | E56: The Singapore Window | F56: Nou | G56: EN | H56: Concept propus; nescris | I56: 60000 | J56: 46325 | K56: 46343 | L56: 46345 | M56: 46347 | N56: LOT D | O56: De contractat / desemnat | P56: Romance contemporan | Q56: O decizie profesională deschide ultima etapă a arcului emoțional. | S56: =COUNTIFS(Editii_300!$B$2:$B$301,A56,Editii_300!$X$2:$X$301,1) -> 0 | T56: =IF(S56=3,1,0) -> 0
A57: DB-056 | B57: AMORIS | C57: Aegean Second Chances | D57: 1 | E57: The Bookshop by the Harbour | F57: Nou | G57: EN | H57: Concept propus; nescris | I57: 55000 | J57: 46311 | K57: 46329 | L57: 46331 | M57: 46333 | N57: LOT B | O57: De contractat / desemnat | P57: Romance independent conectat | Q57: O librară și un restaurator trebuie să salveze același spațiu. | S57: =COUNTIFS(Editii_300!$B$2:$B$301,A57,Editii_300!$X$2:$X$301,1) -> 0 | T57: =IF(S57=3,1,0) -> 0
A58: DB-057 | B58: AMORIS | C58: Aegean Second Chances | D58: 2 | E58: The Olive Harvest | F58: Nou | G58: EN | H58: Concept propus; nescris | I58: 55000 | J58: 46311 | K58: 46329 | L58: 46331 | M58: 46333 | N58: LOT B | O58: De contractat / desemnat | P58: Romance independent conectat | Q58: Foști rivali împart o recoltă și o datorie de familie. | S58: =COUNTIFS(Editii_300!$B$2:$B$301,A58,Editii_300!$X$2:$X$301,1) -> 0 | T58: =IF(S58=3,1,0) -> 0
A59: DB-058 | B59: AMORIS | C59: Aegean Second Chances | D59: 3 | E59: One Summer, Two Keys | F59: Nou | G59: EN | H59: Concept propus; nescris | I59: 55000 | J59: 46311 | K59: 46329 | L59: 46331 | M59: 46333 | N59: LOT B | O59: De contractat / desemnat | P59: Romance independent conectat | Q59: Doi moștenitori primesc cheia aceleiași case. | S59: =COUNTIFS(Editii_300!$B$2:$B$301,A59,Editii_300!$X$2:$X$301,1) -> 0 | T59: =IF(S59=3,1,0) -> 0
...

Sheet Audit_17
A1: WorkID | B1: Colecție | C1: Saga | D1: Titlu | E1: Limbă sursă | F1: Versiuni | G1: Cuvinte brute | H1: Țintă editată | I1: Stare de audit | J1: Corecția necesară | K1: Master candidat — cale | L1: SHA256 sursă | M1: Publicare dovedită
A2: DB-001 | B2: NOIR | C2: Cronicile Transilvaniei | D2: Umbra Trandafirului Negru | E2: RO | F2: V1–V5 | G2: 61721 | H2: 60000 | I2: Manuscris candidat — nevalidat editorial | J2: Materiale de lucru și profiluri înaintea romanului; cronologie de corelat cu site-ul. | K2: D:\00. Downloads\Dracula Book\NOIR SERIES\Umbra Trandafirului Negru Devin.ai\Versiunea 5\MANUSCRIS_COMPLET V5.docx | L2: 0175226a7f5f95264bfe9525582c33ac2acc9e13a6cbf9cb513ab2a57a5ab7d7 | M2: Nu în materialele verificate
A3: DB-002 | B3: NOIR | C3: Cronicile Transilvaniei | D3: Marienburg: Sigiliul Fecioarei | E3: RO | F3: V1–V5 | G3: 76842 | H3: 70000 | I3: Manuscris candidat — nevalidat editorial | J3: Circa 76,8k cuvinte brute, nu 85–95k confirmate; marcaje și epoci de verificat. | K3: D:\00. Downloads\Dracula Book\NOIR SERIES\Marienburg Sigiliul Fecioarei\Versiunea 5\MARIENBURG-SIGILIUL-FECIOAREI-Draft5-Clean.docx | L3: 84ecf1904fb16685c682131c7e526a27dab96526401908da60d4d36f4186ba80 | M3: Nu în materialele verificate
A4: DB-003 | B4: NOIR | C4: Cronicile Transilvaniei | D4: Sânge și Sare la Schäßburg | E4: RO | F4: V1 | G4: 95457 | H4: 80000 | I4: Manuscris candidat — nevalidat editorial | J4: Titlul interior diferă de copertă/site; prefată de proces AI și note de eliminat. | K4: D:\00. Downloads\Dracula Book\NOIR SERIES\Sânge și Sare la Schäßburg\Versiunea 1\CIVITAS_SEX_LEGAMANTUL_DE_SARE.docx | L4: 46bba731100a53b08d5e358a8387aac78213609412b57560206734b8301b2137 | M4: Nu în materialele verificate
A5: DB-036 | B5: AMORIS | C5: Alex Damian | D5: Beneath the Skin of the Sea | E5: EN | F5: V1 | G5: 80329 | H5: 80000 | I5: Manuscris candidat — nevalidat editorial | J5: Raportul intern de 9,87/10 nu dovedește recenzie independentă sau publicare. | K5: D:\00. Downloads\Dracula Book\AMORIS SERIES\BENEATH THE SKIN OF THE SEA\Versiunea 1\BENEATH_THE_SKIN_OF_THE_SEA_Complete_Novel.docx | L5: 4ebf04663fb5ee0ac9c0aa0ef26bd2d8c8222d95db93d16cbb372b7f8e7bf44c | M5: Nu în materialele verificate
A6: DB-037 | B6: AMORIS | C6: Alex Damian | D6: Shadows in the Port | E6: EN | F6: V1 | G6: 109258 | H6: 90000 | I6: Manuscris candidat — nevalidat editorial | J6: Alex/Elena și început apropiat de Beneath; verificare sequel vs rescriere; heading 5 neidentificat. | K6: D:\00. Downloads\Dracula Book\AMORIS SERIES\Shadows in the Port\Versiunea 1\Shadows in the Port V1.docx | L6: 3f5fc3d81f584d23e7d029e90ebe2d40f7b25c5a24dfa78a81f0c2ff58e11b47 | M6: Nu în materialele verificate
A7: DB-046 | B7: AMORIS | C7: Isabella Morgan / Rue des Âmes | D7: Hotelul din Rue des Âmes | E7: EN | F7: V2 validă | G7: 96056 | H7: 85000 | I7: Manuscris candidat — nevalidat editorial | J7: Folderul V1 conține copie identică a Aurora 1; heading CHAPTER 11 neidentificat; nu se deduce automat lipsa prozei. | K7: D:\00. Downloads\Dracula Book\AMORIS SERIES\Hotelul din Rue des Âmes\Versiunea 2\Hotelul_din_Rue_des_Ames_FINAL_v2.docx | L7: a9940d5776380cb40b105429f6976219440f3ea74fb8ebc1d1b4481e9da068c3 | M7: Nu în materialele verificate
A8: DB-071 | B8: MYTHICA | C8: Saga Celor Zece Coroane | D8: The Northern Crown | E8: EN | F8: V1–V3 | G8: 106845 | H8: 95000 | I8: Manuscris candidat — nevalidat editorial | J8: Finalul anunță The Eastern Sands; planul arhivat numește vol.2 The Crown of Waters. | K8: D:\00. Downloads\Dracula Book\MYTHICA SERIES\Saga Celor Zece Coroane\Cartea 1 The_Northern_Crown\Versiunea 3\Book-1-The-Northern-Crown-EDITED-FINAL.docx | L8: c77846fdc094d5800735ab8bdc7a1a3f62248a313f5cf2ae6e757e8baef22039 | M8: Nu în materialele verificate
A9: DB-091 | B9: AURORA | C9: Ciclul Aurora | D9: The First Light | E9: EN | F9: V1–V2 | G9: 193758 | H9: 90000 | I9: Manuscris candidat — nevalidat editorial | J9: V2 circa 193,8k brute; reducere țintită propusă; metanote de proces în text. | K9: D:\00. Downloads\Dracula Book\DRACULA AURORA\Book 1\Versiunea 2\AURORA_Book1_DEVIN_FINAL.docx | L9: d187e77694194bec8887f6f7b816b27fe1938496ccf6307823205a0eb2f16eb7 | M9: Nu în materialele verificate
A10: DB-092 | B10: AURORA | C10: Ciclul Aurora | D10: We Meet at Sunrise | E10: EN | F10: V1–V2 | G10: 86474 | H10: 75000 | I10: Manuscris candidat — nevalidat editorial | J10: V1 circa 33,7k, V2 circa 86,5k; schimbare majoră, de ales master după lectură comparată. | K10: D:\00. Downloads\Dracula Book\DRACULA AURORA\Book 2\Versiunea 2\we_meet_at_sunrise_FINAL_LOCAL_LLM.docx | L10: 8211280c2445d6096b700239b9a7391c943f22c47669b159a674b257f34cc85d | M10: Nu în materialele verificate
A11: DB-093 | B11: AURORA | C11: Ciclul Aurora | D11: The Atlas of Tomorrow | E11: EN | F11: V1 | G11: 12994 | H11: 30000 | I11: Manuscris candidat — nevalidat editorial | J11: Circa 13k, 15 capitole; interior CV for a Dreamer; nu este roman lung. | K11: D:\00. Downloads\Dracula Book\DRACULA AURORA\Book 3\Versiunea 1\Aurora Book3 The Atlas of Tomorrow.docx | L11: d317c19d9fb4fe329d30e7a41e76baa9f92b5d3ce814b24d02cee07f19c80c58 | M11: Nu în materialele verificate
A12: DB-094 | B12: AURORA | C12: Ciclul Aurora | D12: Between Two Addresses | E12: EN | F12: V1 + interior | G12: 25702 | H12: 28000 | I12: Manuscris candidat — nevalidat editorial | J12: Text scurt; placeholder-uri în sursă; interiorul de publicare trebuie comparat. | K12: D:\00. Downloads\Dracula Book\DRACULA AURORA\Book 4\Versiunea 1\BetweenTwoAddresses_Complete.docx | L12: 407b05543d4c56093cd4bbc917cde2d4156c2052dbd8b4fd9960de7259e2627a | M12: Nu în materialele verificate
A13: DB-095 | B13: AURORA | C13: Ciclul Aurora | D13: Dawn of Courage | E13: EN | F13: V1 + interior | G13: 36148 | H13: 36000 | I13: Manuscris candidat — nevalidat editorial | J13: Sursa indică Volume 1 deși este Book 5 în catalog; metanote AI. | K13: D:\00. Downloads\Dracula Book\DRACULA AURORA\Book 5\Versiunea 1\DAWN_OF_COURAGE_COMPLETE_20251014_110553.docx | L13: 77f284875201cfa8867353b78fe6ac4eec7c3e23b7220fed384228705f0136a9 | M13: Nu în materialele verificate
... A18: DB-100 | B18: AURORA | C18: Ciclul Aurora | D18: Aurora Compass | E18: EN | F18: V1 + interior | G18: 27748 | H18: 30000 | I18: Manuscris candidat — nevalidat editorial | J18: Autor generic în sursă versus pseudonim comercial; metanote REVISED. | K18: D:\00. Downloads\Dracula Book\DRACULA AURORA\Book 10\Versiunea 1\Aurora_Compass_Complete_Novel.docx | L18: 1880b16da36e2a3297f526b15b2fd582963c592eb9d2595a5c3cc620e4c6e428 | M18: Nu în materialele verificate

Sheet Saga_12
A1: Colecție | B1: Saga | C1: Fond candidat | D1: Noi | E1: Total titluri | F1: Total ediții | G1: Cuvinte master
A2: NOIR | B2: Cronicile Transilvaniei | C2: 3 | D2: 7 | E2: 10 | F2: 30 | G2: 630000
A3: NOIR | B3: Carpathian Cold Cases | C3: 0 | D3: 10 | E3: 10 | F3: 30 | G3: 550000
A4: NOIR | B4: The Black Archive | C4: 0 | D4: 10 | E4: 10 | F4: 30 | G4: 350000
A5: NOIR | B5: The Borderland Files | C5: 0 | D5: 5 | E5: 5 | F5: 15 | G5: 175000
A6: AMORIS | B6: Alex Damian | C6: 2 | D6: 8 | E6: 10 | F6: 30 | G6: 650000
A7: AMORIS | B7: Isabella Morgan / Rue des Âmes | C7: 1 | D7: 9 | E7: 10 | F7: 30 | G7: 625000
A8: AMORIS | B8: Aegean Second Chances | C8: 0 | D8: 10 | E8: 10 | F8: 30 | G8: 550000
A9: AMORIS | B9: Midnight Letters | C9: 0 | D9: 5 | E9: 5 | F9: 15 | G9: 175000
A10: MYTHICA | B10: Saga Celor Zece Coroane | C10: 1 | D10: 9 | E10: 10 | F10: 30 | G10: 770000
A11: MYTHICA | B11: The Thorn Covenant | C11: 0 | D11: 5 | E11: 5 | F11: 15 | G11: 325000
A12: MYTHICA | B12: Tales of the Border Realms | C12: 0 | D12: 5 | E12: 5 | F12: 15 | G12: 200000
A13: AURORA | B13: Ciclul Aurora | C13: 10 | D13: 0 | E13: 10 | F13: 30 | G13: 419000

Sheet Editii_300
A1: EditionID | B1: WorkID | C1: Colecție | D1: Saga | E1: Volum | F1: Titlu de lucru | G1: Limbă ediție | H1: Limbă sursă | I1: Operațiune | J1: Stare | K1: Responsabil | L1: Cuvinte sursă țintă | M1: Master blocat țintă | N1: Traduceri țintă | O1: QA țintă | P1: Publicare țintă | Q1: Aprobator editorial | R1: Data publicării reale | S1: URL dovadă acces/livrare | T1: ISBN / ID extern, dacă e cazul | U1: Checksum master final | V1: Drepturi | W1: Observații | X1: Publicare verificată
A2: DB-001-EN | B2: DB-001 | C2: NOIR | D2: Cronicile Transilvaniei | E2: 1 | F2: Umbra Trandafirului Negru | G2: EN | H2: RO | I2: Traducere RO→EN | J2: Planificat | K2: De desemnat | L2: =Catalog_100!I2 -> 60000 | M2: =Catalog_100!J2 -> 46298 | N2: =Catalog_100!K2 -> 46301 | O2: =Catalog_100!L2 -> 46303 | P2: =Catalog_100!M2 -> 46305 | V2: Neconfirmat | W2: Fără ediție finală confirmată | X2: =IF(AND(J2="Publicat",Q2<>"",ISNUMBER(R2),S2<>"",U2<>"",V2="Confirmat"),1,0) -> 0
A3: DB-001-RO | B3: DB-001 | C3: NOIR | D3: Cronicile Transilvaniei | E3: 1 | F3: Umbra Trandafirului Negru | G3: RO | H3: RO | I3: Editare fond | J3: Manuscris existent | K3: De desemnat | L3: =Catalog_100!I2 -> 60000 | M3: =Catalog_100!J2 -> 46298 | N3: =Catalog_100!K2 -> 46301 | O3: =Catalog_100!L2 -> 46303 | P3: =Catalog_100!M2 -> 46305 | V3: Neconfirmat | W3: Materiale de lucru și profiluri înaintea romanului; cronologie de corelat cu site-ul. | X3: =IF(AND(J3="Publicat",Q3<>"",ISNUMBER(R3),S3<>"",U3<>"",V3="Confirmat"),1,0) -> 0
A4: DB-001-DE | B4: DB-001 | C4: NOIR | D4: Cronicile Transilvaniei | E4: 1 | F4: Umbra Trandafirului Negru | G4: DE | H4: RO | I4: Traducere RO→DE | J4: Planificat | K4: De desemnat | L4: =Catalog_100!I2 -> 60000 | M4: =Catalog_100!J2 -> 46298 | N4: =Catalog_100!K2 -> 46301 | O4: =Catalog_100!L2 -> 46303 | P4: =Catalog_100!M2 -> 46305 | V4: Neconfirmat | W4: Fără ediție finală confirmată | X4: =IF(AND(J4="Publicat",Q4<>"",ISNUMBER(R4),S4<>"",U4<>"",V4="Confirmat"),1,0) -> 0
A5: DB-002-EN | B5: DB-002 | C5: NOIR | D5: Cronicile Transilvaniei | E5: 2 | F5: Marienburg: Sigiliul Fecioarei | G5: EN | H5: RO | I5: Traducere RO→EN | J5: Planificat | K5: De desemnat | L5: =Catalog_100!I3 -> 70000 | M5: =Catalog_100!J3 -> 46305 | N5: =Catalog_100!K3 -> 46315 | O5: =Catalog_100!L3 -> 46317 | P5: =Catalog_100!M3 -> 46319 | V5: Neconfirmat | W5: Fără ediție finală confirmată | X5: =IF(AND(J5="Publicat",Q5<>"",ISNUMBER(R5),S5<>"",U5<>"",V5="Confirmat"),1,0) -> 0
A6: DB-002-RO | B6: DB-002 | C6: NOIR | D6: Cronicile Transilvaniei | E6: 2 | F6: Marienburg: Sigiliul Fecioarei | G6: RO | H6: RO | I6: Editare fond | J6: Manuscris existent | K6: De desemnat | L6: =Catalog_100!I3 -> 70000 | M6: =Catalog_100!J3 -> 46305 | N6: =Catalog_100!K3 -> 46315 | O6: =Catalog_100!L3 -> 46317 | P6: =Catalog_100!M3 -> 46319 | V6: Neconfirmat | W6: Circa 76,8k cuvinte brute, nu 85–95k confirmate; marcaje și epoci de verificat. | X6: =IF(AND(J6="Publicat",Q6<>"",ISNUMBER(R6),S6<>"",U6<>"",V6="Confirmat"),1,0) -> 0
A7: DB-002-DE | B7: DB-002 | C7: NOIR | D7: Cronicile Transilvaniei | E7: 2 | F7: Marienburg: Sigiliul Fecioarei | G7: DE | H7: RO | I7: Traducere RO→DE | J7: Planificat | K7: De desemnat | L7: =Catalog_100!I3 -> 70000 | M7: =Catalog_100!J3 -> 46305 | N7: =Catalog_100!K3 -> 46315 | O7: =Catalog_100!L3 -> 46317 | P7: =Catalog_100!M3 -> 46319 | V7: Neconfirmat | W7: Fără ediție finală confirmată | X7: =IF(AND(J7="Publicat",Q7<>"",ISNUMBER(R7),S7<>"",U7<>"",V7="Confirmat"),1,0) -> 0
A8: DB-003-EN | B8: DB-003 | C8: NOIR | D8: Cronicile Transilvaniei | E8: 3 | F8: Sânge și Sare la Schäßburg | G8: EN | H8: RO | I8: Traducere RO→EN | J8: Planificat | K8: De desemnat | L8: =Catalog_100!I4 -> 80000 | M8: =Catalog_100!J4 -> 46305 | N8: =Catalog_100!K4 -> 46315 | O8: =Catalog_100!L4 -> 46317 | P8: =Catalog_100!M4 -> 46319 | V8: Neconfirmat | W8: Fără ediție finală confirmată | X8: =IF(AND(J8="Publicat",Q8<>"",ISNUMBER(R8),S8<>"",U8<>"",V8="Confirmat"),1,0) -> 0
A9: DB-003-RO | B9: DB-003 | C9: NOIR | D9: Cronicile Transilvaniei | E9: 3 | F9: Sânge și Sare la Schäßburg | G9: RO | H9: RO | I9: Editare fond | J9: Manuscris existent | K9: De desemnat | L9: =Catalog_100!I4 -> 80000 | M9: =Catalog_100!J4 -> 46305 | N9: =Catalog_100!K4 -> 46315 | O9: =Catalog_100!L4 -> 46317 | P9: =Catalog_100!M4 -> 46319 | V9: Neconfirmat | W9: Titlul interior diferă de copertă/site; prefată de proces AI și note de eliminat. | X9: =IF(AND(J9="Publicat",Q9<>"",ISNUMBER(R9),S9<>"",U9<>"",V9="Confirmat"),1,0) -> 0
A10: DB-003-DE | B10: DB-003 | C10: NOIR | D10: Cronicile Transilvaniei | E10: 3 | F10: Sânge și Sare la Schäßburg | G10: DE | H10: RO | I10: Traducere RO→DE | J10: Planificat | K10: De desemnat | L10: =Catalog_100!I4 -> 80000 | M10: =Catalog_100!J4 -> 46305 | N10: =Catalog_100!K4 -> 46315 | O10: =Catalog_100!L4 -> 46317 | P10: =Catalog_100!M4 -> 46319 | V10: Neconfirmat | W10: Fără ediție finală confirmată | X10: =IF(AND(J10="Publicat",Q10<>"",ISNUMBER(R10),S10<>"",U10<>"",V10="Confirmat"),1,0) -> 0
A11: DB-004-EN | B11: DB-004 | C11: NOIR | D11: Cronicile Transilvaniei | E11: 4 | F11: The Bellmaker of Brașov | G11: EN | H11: EN | I11: Scriere nouă | J11: Planificat | K11: De desemnat | L11: =Catalog_100!I5 -> 60000 | M11: =Catalog_100!J5 -> 46318 | N11: =Catalog_100!K5 -> 46336 | O11: =Catalog_100!L5 -> 46338 | P11: =Catalog_100!M5 -> 46340 | V11: Neconfirmat | W11: Fără ediție finală confirmată | X11: =IF(AND(J11="Publicat",Q11<>"",ISNUMBER(R11),S11<>"",U11<>"",V11="Confirmat"),1,0) -> 0
A12: DB-004-RO | B12: DB-004 | C12: NOIR | D12: Cronicile Transilvaniei | E12: 4 | F12: The Bellmaker of Brașov | G12: RO | H12: EN | I12: Traducere EN→RO | J12: Planificat | K12: De desemnat | L12: =Catalog_100!I5 -> 60000 | M12: =Catalog_100!J5 -> 46318 | N12: =Catalog_100!K5 -> 46336 | O12: =Catalog_100!L5 -> 46338 | P12: =Catalog_100!M5 -> 46340 | V12: Neconfirmat | W12: Fără ediție finală confirmată | X12: =IF(AND(J12="Publicat",Q12<>"",ISNUMBER(R12),S12<>"",U12<>"",V12="Confirmat"),1,0) -> 0
A13: DB-004-DE | B13: DB-004 | C13: NOIR | D13: Cronicile Transilvaniei | E13: 4 | F13: The Bellmaker of Brașov | G13: DE | H13: EN | I13: Traducere EN→DE | J13: Planificat | K13: De desemnat | L13: =Catalog_100!I5 -> 60000 | M13: =Catalog_100!J5 -> 46318 | N13: =Catalog_100!K5 -> 46336 | O13: =Catalog_100!L5 -> 46338 | P13: =Catalog_100!M5 -> 46340 | V13: Neconfirmat | W13: Fără ediție finală confirmată | X13: =IF(AND(J13="Publicat",Q13<>"",ISNUMBER(R13),S13<>"",U13<>"",V13="Confirmat"),1,0) -> 0
A14: DB-005-EN | B14: DB-005 | C14: NOIR | D14: Cronicile Transilvaniei | E14: 5 | F14: The Sibiu Testament | G14: EN | H14: EN | I14: Scriere nouă | J14: Planificat | K14: De desemnat | L14: =Catalog_100!I6 -> 60000 | M14: =Catalog_100!J6 -> 46318 | N14: =Catalog_100!K6 -> 46336 | O14: =Catalog_100!L6 -> 46338 | P14: =Catalog_100!M6 -> 46340 | V14: Neconfirmat | W14: Fără ediție finală confirmată | X14: =IF(AND(J14="Publicat",Q14<>"",ISNUMBER(R14),S14<>"",U14<>"",V14="Confirmat"),1,0) -> 0
A15: DB-005-RO | B15: DB-005 | C15: NOIR | D15: Cronicile Transilvaniei | E15: 5 | F15: The Sibiu Testament | G15: RO | H15: EN | I15: Traducere EN→RO | J15: Planificat | K15: De desemnat | L15: =Catalog_100!I6 -> 60000 | M15: =Catalog_100!J6 -> 46318 | N15: =Catalog_100!K6 -> 46336 | O15: =Catalog_100!L6 -> 46338 | P15: =Catalog_100!M6 -> 46340 | V15: Neconfirmat | W15: Fără ediție finală confirmată | X15: =IF(AND(J15="Publicat",Q15<>"",ISNUMBER(R15),S15<>"",U15<>"",V15="Confirmat"),1,0) -> 0
A16: DB-005-DE | B16: DB-005 | C16: NOIR | D16: Cronicile Transilvaniei | E16: 5 | F16: The Sibiu Testament | G16: DE | H16: EN | I16: Traducere EN→DE | J16: Planificat | K16: De desemnat | L16: =Catalog_100!I6 -> 60000 | M16: =Catalog_100!J6 -> 46318 | N16: =Catalog_100!K6 -> 46336 | O16: =Catalog_100!L6 -> 46338 | P16: =Catalog_100!M6 -> 46340 | V16: Neconfirmat | W16: Fără ediție finală confirmată | X16: =IF(AND(J16="Publicat",Q16<>"",ISNUMBER(R16),S16<>"",U16<>"",V16="Confirmat"),1,0) -> 0
A17: DB-006-EN | B17: DB-006 | C17: NOIR | D17: Cronicile Transilvaniei | E17: 6 | F17: The Bistrița Bride | G17: EN | H17: EN | I17: Scriere nouă | J17: Planificat | K17: De desemnat | L17: =Catalog_100!I7 -> 60000 | M17: =Catalog_100!J7 -> 46318 | N17: =Catalog_100!K7 -> 46336 | O17: =Catalog_100!L7 -> 46338 | P17: =Catalog_100!M7 -> 46340 | V17: Neconfirmat | W17: Fără ediție finală confirmată | X17: =IF(AND(J17="Publicat",Q17<>"",ISNUMBER(R17),S17<>"",U17<>"",V17="Confirmat"),1,0) -> 0
A18: DB-006-RO | B18: DB-006 | C18: NOIR | D18: Cronicile Transilvaniei | E18: 6 | F18: The Bistrița Bride | G18: RO | H18: EN | I18: Traducere EN→RO | J18: Planificat | K18: De desemnat | L18: =Catalog_100!I7 -> 60000 | M18: =Catalog_100!J7 -> 46318 | N18: =Catalog_100!K7 -> 46336 | O18: =Catalog_100!L7 -> 46338 | P18: =Catalog_100!M7 -> 46340 | V18: Neconfirmat | W18: Fără ediție finală confirmată | X18: =IF(AND(J18="Publicat",Q18<>"",ISNUMBER(R18),S18<>"",U18<>"",V18="Confirmat"),1,0) -> 0
A19: DB-006-DE | B19: DB-006 | C19: NOIR | D19: Cronicile Transilvaniei | E19: 6 | F19: The Bistrița Bride | G19: DE | H19: EN | I19: Traducere EN→DE | J19: Planificat | K19: De desemnat | L19: =Catalog_100!I7 -> 60000 | M19: =Catalog_100!J7 -> 46318 | N19: =Catalog_100!K7 -> 46336 | O19: =Catalog_100!L7 -> 46338 | P19: =Catalog_100!M7 -> 46340 | V19: Neconfirmat | W19: Fără ediție finală confirmată | X19: =IF(AND(J19="Publicat",Q19<>"",ISNUMBER(R19),S19<>"",U19<>"",V19="Confirmat"),1,0) -> 0
A20: DB-007-EN | B20: DB-007 | C20: NOIR | D20: Cronicile Transilvaniei | E20: 7 | F20: The Locksmith of Sighișoara | G20: EN | H20: EN | I20: Scriere nouă | J20: Planificat | K20: De desemnat | L20: =Catalog_100!I8 -> 60000 | M20: =Catalog_100!J8 -> 46318 | N20: =Catalog_100!K8 -> 46336 | O20: =Catalog_100!L8 -> 46338 | P20: =Catalog_100!M8 -> 46340 | V20: Neconfirmat | W20: Fără ediție finală confirmată | X20: =IF(AND(J20="Publicat",Q20<>"",ISNUMBER(R20),S20<>"",U20<>"",V20="Confirmat"),1,0) -> 0
A21: DB-007-RO | B21: DB-007 | C21: NOIR | D21: Cronicile Transilvaniei | E21: 7 | F21: The Locksmith of Sighișoara | G21: RO | H21: EN | I21: Traducere EN→RO | J21: Planificat | K21: De desemnat | L21: =Catalog_100!I8 -> 60000 | M21: =Catalog_100!J8 -> 46318 | N21: =Catalog_100!K8 -> 46336 | O21: =Catalog_100!L8 -> 46338 | P21: =Catalog_100!M8 -> 46340 | V21: Neconfirmat | W21: Fără ediție finală confirmată | X21: =IF(AND(J21="Publicat",Q21<>"",ISNUMBER(R21),S21<>"",U21<>"",V21="Confirmat"),1,0) -> 0
A22: DB-007-DE | B22: DB-007 | C22: NOIR | D22: Cronicile Transilvaniei | E22: 7 | F22: The Locksmith of Sighișoara | G22: DE | H22: EN | I22: Traducere EN→DE | J22: Planificat | K22: De desemnat | L22: =Catalog_100!I8 -> 60000 | M22: =Catalog_100!J8 -> 46318 | N22: =Catalog_100!K8 -> 46336 | O22: =Catalog_100!L8 -> 46338 | P22: =Catalog_100!M8 -> 46340 | V22: Neconfirmat | W22: Fără ediție finală confirmată | X22: =IF(AND(J22="Publicat",Q22<>"",ISNUMBER(R22),S22<>"",U22<>"",V22="Confirmat"),1,0) -> 0
A23: DB-008-EN | B23: DB-008 | C23: NOIR | D23: Cronicile Transilvaniei | E23: 8 | F23: The Alba Iulia Cipher | G23: EN | H23: EN | I23: Scriere nouă | J23: Planificat | K23: De desemnat | L23: =Catalog_100!I9 -> 60000 | M23: =Catalog_100!J9 -> 46318 | N23: =Catalog_100!K9 -> 46336 | O23: =Catalog_100!L9 -> 46338 | P23: =Catalog_100!M9 -> 46340 | V23: Neconfirmat | W23: Fără ediție finală confirmată | X23: =IF(AND(J23="Publicat",Q23<>"",ISNUMBER(R23),S23<>"",U23<>"",V23="Confirmat"),1,0) -> 0
A24: DB-008-RO | B24: DB-008 | C24: NOIR | D24: Cronicile Transilvaniei | E24: 8 | F24: The Alba Iulia Cipher | G24: RO | H24: EN | I24: Traducere EN→RO | J24: Planificat | K24: De desemnat | L24: =Catalog_100!I9 -> 60000 | M24: =Catalog_100!J9 -> 46318 | N24: =Catalog_100!K9 -> 46336 | O24: =Catalog_100!L9 -> 46338 | P24: =Catalog_100!M9 -> 46340 | V24: Neconfirmat | W24: Fără ediție finală confirmată | X24: =IF(AND(J24="Publicat",Q24<>"",ISNUMBER(R24),S24<>"",U24<>"",V24="Confirmat"),1,0) -> 0
A25: DB-008-DE | B25: DB-008 | C25: NOIR | D25: Cronicile Transilvaniei | E25: 8 | F25: The Alba Iulia Cipher | G25: DE | H25: EN | I25: Traducere EN→DE | J25: Planificat | K25: De desemnat | L25: =Catalog_100!I9 -> 60000 | M25: =Catalog_100!J9 -> 46318 | N25: =Catalog_100!K9 -> 46336 | O25: =Catalog_100!L9 -> 46338 | P25: =Catalog_100!M9 -> 46340 | V25: Neconfirmat | W25: Fără ediție finală confirmată | X25: =IF(AND(J25="Publicat",Q25<>"",ISNUMBER(R25),S25<>"",U25<>"",V25="Confirmat"),1,0) -> 0
A26: DB-009-EN | B26: DB-009 | C26: NOIR | D26: Cronicile Transilvaniei | E26: 9 | F26: The Winter Court of Bran | G26: EN | H26: EN | I26: Scriere nouă | J26: Planificat | K26: De desemnat | L26: =Catalog_100!I10 -> 60000 | M26: =Catalog_100!J10 -> 46318 | N26: =Catalog_100!K10 -> 46336 | O26: =Catalog_100!L10 -> 46338 | P26: =Catalog_100!M10 -> 46340 | V26: Neconfirmat | W26: Fără ediție finală confirmată | X26: =IF(AND(J26="Publicat",Q26<>"",ISNUMBER(R26),S26<>"",U26<>"",V26="Confirmat"),1,0) -> 0
A27: DB-009-RO | B27: DB-009 | C27: NOIR | D27: Cronicile Transilvaniei | E27: 9 | F27: The Winter Court of Bran | G27: RO | H27: EN | I27: Traducere EN→RO | J27: Planificat | K27: De desemnat | L27: =Catalog_100!I10 -> 60000 | M27: =Catalog_100!J10 -> 46318 | N27: =Catalog_100!K10 -> 46336 | O27: =Catalog_100!L10 -> 46338 | P27: =Catalog_100!M10 -> 46340 | V27: Neconfirmat | W27: Fără ediție finală confirmată | X27: =IF(AND(J27="Publicat",Q27<>"",ISNUMBER(R27),S27<>"",U27<>"",V27="Confirmat"),1,0) -> 0
A28: DB-009-DE | B28: DB-009 | C28: NOIR | D28: Cronicile Transilvaniei | E28: 9 | F28: The Winter Court of Bran | G28: DE | H28: EN | I28: Traducere EN→DE | J28: Planificat | K28: De desemnat | L28: =Catalog_100!I10 -> 60000 | M28: =Catalog_100!J10 -> 46318 | N28: =Catalog_100!K10 -> 46336 | O28: =Catalog_100!L10 -> 46338 | P28: =Catalog_100!M10 -> 46340 | V28: Neconfirmat | W28: Fără ediție finală confirmată | X28: =IF(AND(J28="Publicat",Q28<>"",ISNUMBER(R28),S28<>"",U28<>"",V28="Confirmat"),1,0) -> 0
A29: DB-010-EN | B29: DB-010 | C29: NOIR | D29: Cronicile Transilvaniei | E29: 10 | F29: The Last Black Rose | G29: EN | H29: EN | I29: Scriere nouă | J29: Planificat | K29: De desemnat | L29: =Catalog_100!I11 -> 60000 | M29: =Catalog_100!J11 -> 46318 | N29: =Catalog_100!K11 -> 46336 | O29: =Catalog_100!L11 -> 46338 | P29: =Catalog_100!M11 -> 46340 | V29: Neconfirmat | W29: Fără ediție finală confirmată | X29: =IF(AND(J29="Publicat",Q29<>"",ISNUMBER(R29),S29<>"",U29<>"",V29="Confirmat"),1,0) -> 0
A30: DB-010-RO | B30: DB-010 | C30: NOIR | D30: Cronicile Transilvaniei | E30: 10 | F30: The Last Black Rose | G30: RO | H30: EN | I30: Traducere EN→RO | J30: Planificat | K30: De desemnat | L30: =Catalog_100!I11 -> 60000 | M30: =Catalog_100!J11 -> 46318 | N30: =Catalog_100!K11 -> 46336 | O30: =Catalog_100!L11 -> 46338 | P30: =Catalog_100!M11 -> 46340 | V30: Neconfirmat | W30: Fără ediție finală confirmată | X30: =IF(AND(J30="Publicat",Q30<>"",ISNUMBER(R30),S30<>"",U30<>"",V30="Confirmat"),1,0) -> 0
A31: DB-010-DE | B31: DB-010 | C31: NOIR | D31: Cronicile Transilvaniei | E31: 10 | F31: The Last Black Rose | G31: DE | H31: EN | I31: Traducere EN→DE | J31: Planificat | K31: De desemnat | L31: =Catalog_100!I11 -> 60000 | M31: =Catalog_100!J11 -> 46318 | N31: =Catalog_100!K11 -> 46336 | O31: =Catalog_100!L11 -> 46338 | P31: =Catalog_100!M11 -> 46340 | V31: Neconfirmat | W31: Fără ediție finală confirmată | X31: =IF(AND(J31="Publicat",Q31<>"",ISNUMBER(R31),S31<>"",U31<>"",V31="Confirmat"),1,0) -> 0
A32: DB-011-EN | B32: DB-011 | C32: NOIR | D32: Carpathian Cold Cases | E32: 1 | F32: The Witness Beneath the Ice | G32: EN | H32: EN | I32: Scriere nouă | J32: Planificat | K32: De desemnat | L32: =Catalog_100!I12 -> 55000 | M32: =Catalog_100!J12 -> 46311 | N32: =Catalog_100!K12 -> 46329 | O32: =Catalog_100!L12 -> 46331 | P32: =Catalog_100!M12 -> 46333 | V32: Neconfirmat | W32: Fără ediție finală confirmată | X32: =IF(AND(J32="Publicat",Q32<>"",ISNUMBER(R32),S32<>"",U32<>"",V32="Confirmat"),1,0) -> 0
A33: DB-011-RO | B33: DB-011 | C33: NOIR | D33: Carpathian Cold Cases | E33: 1 | F33: The Witness Beneath the Ice | G33: RO | H33: EN | I33: Traducere EN→RO | J33: Planificat | K33: De desemnat | L33: =Catalog_100!I12 -> 55000 | M33: =Catalog_100!J12 -> 46311 | N33: =Catalog_100!K12 -> 46329 | O33: =Catalog_100!L12 -> 46331 | P33: =Catalog_100!M12 -> 46333 | V33: Neconfirmat | W33: Fără ediție finală confirmată | X33: =IF(AND(J33="Publicat",Q33<>"",ISNUMBER(R33),S33<>"",U33<>"",V33="Confirmat"),1,0) -> 0
A34: DB-011-DE | B34: DB-011 | C34: NOIR | D34: Carpathian Cold Cases | E34: 1 | F34: The Witness Beneath the Ice | G34: DE | H34: EN | I34: Traducere EN→DE | J34: Planificat | K34: De desemnat | L34: =Catalog_100!I12 -> 55000 | M34: =Catalog_100!J12 -> 46311 | N34: =Catalog_100!K12 -> 46329 | O34: =Catalog_100!L12 -> 46331 | P34: =Catalog_100!M12 -> 46333 | V34: Neconfirmat | W34: Fără ediție finală confirmată | X34: =IF(AND(J34="Publicat",Q34<>"",ISNUMBER(R34),S34<>"",U34<>"",V34="Confirmat"),1,0) -> 0
A35: DB-012-EN | B35: DB-012 | C35: NOIR | D35: Carpathian Cold Cases | E35: 2 | F35: The Missing Carriage | G35: EN | H35: EN | I35: Scriere nouă | J35: Planificat | K35: De desemnat | L35: =Catalog_100!I13 -> 55000 | M35: =Catalog_100!J13 -> 46311 | N35: =Catalog_100!K13 -> 46329 | O35: =Catalog_100!L13 -> 46331 | P35: =Catalog_100!M13 -> 46333 | V35: Neconfirmat | W35: Fără ediție finală confirmată | X35: =IF(AND(J35="Publicat",Q35<>"",ISNUMBER(R35),S35<>"",U35<>"",V35="Confirmat"),1,0) -> 0
A36: DB-012-RO | B36: DB-012 | C36: NOIR | D36: Carpathian Cold Cases | E36: 2 | F36: The Missing Carriage | G36: RO | H36: EN | I36: Traducere EN→RO | J36: Planificat | K36: De desemnat | L36: =Catalog_100!I13 -> 55000 | M36: =Catalog_100!J13 -> 46311 | N36: =Catalog_100!K13 -> 46329 | O36: =Catalog_100!L13 -> 46331 | P36: =Catalog_100!M13 -> 46333 | V36: Neconfirmat | W36: Fără ediție finală confirmată | X36: =IF(AND(J36="Publicat",Q36<>"",ISNUMBER(R36),S36<>"",U36<>"",V36="Confirmat"),1,0) -> 0
A37: DB-012-DE | B37: DB-012 | C37: NOIR | D37: Carpathian Cold Cases | E37: 2 | F37: The Missing Carriage | G37: DE | H37: EN | I37: Traducere EN→DE | J37: Planificat | K37: De desemnat | L37: =Catalog_100!I13 -> 55000 | M37: =Catalog_100!J13 -> 46311 | N37: =Catalog_100!K13 -> 46329 | O37: =Catalog_100!L13 -> 46331 | P37: =Catalog_100!M13 -> 46333 | V37: Neconfirmat | W37: Fără ediție finală confirmată | X37: =IF(AND(J37="Publicat",Q37<>"",ISNUMBER(R37),S37<>"",U37<>"",V37="Confirmat"),1,0) -> 0
A38: DB-013-EN | B38: DB-013 | C38: NOIR | D38: Carpathian Cold Cases | E38: 3 | F38: The Village That Forgot Her | G38: EN | H38: EN | I38: Scriere nouă | J38: Planificat | K38: De desemnat | L38: =Catalog_100!I14 -> 55000 | M38: =Catalog_100!J14 -> 46311 | N38: =Catalog_100!K14 -> 46329 | O38: =Catalog_100!L14 -> 46331 | P38: =Catalog_100!M14 -> 46333 | V38: Neconfirmat | W38: Fără ediție finală confirmată | X38: =IF(AND(J38="Publicat",Q38<>"",ISNUMBER(R38),S38<>"",U38<>"",V38="Confirmat"),1,0) -> 0
A39: DB-013-RO | B39: DB-013 | C39: NOIR | D39: Carpathian Cold Cases | E39: 3 | F39: The Village That Forgot Her | G39: RO | H39: EN | I39: Traducere EN→RO | J39: Planificat | K39: De desemnat | L39: =Catalog_100!I14 -> 55000 | M39: =Catalog_100!J14 -> 46311 | N39: =Catalog_100!K14 -> 46329 | O39: =Catalog_100!L14 -> 46331 | P39: =Catalog_100!M14 -> 46333 | V39: Neconfirmat | W39: Fără ediție finală confirmată | X39: =IF(AND(J39="Publicat",Q39<>"",ISNUMBER(R39),S39<>"",U39<>"",V39="Confirmat"),1,0) -> 0
A40: DB-013-DE | B40: DB-013 | C40: NOIR | D40: Carpathian Cold Cases | E40: 3 | F40: The Village That Forgot Her | G40: DE | H40: EN | I40: Traducere EN→DE | J40: Planificat | K40: De desemnat | L40: =Catalog_100!I14 -> 55000 | M40: =Catalog_100!J14 -> 46311 | N40: =Catalog_100!K14 -> 46329 | O40: =Catalog_100!L14 -> 46331 | P40: =Catalog_100!M14 -> 46333 | V40: Neconfirmat | W40: Fără ediție finală confirmată | X40: =IF(AND(J40="Publicat",Q40<>"",ISNUMBER(R40),S40<>"",U40<>"",V40="Confirmat"),1,0) -> 0
...

Sheet Calendar
A1: Interval | B1: Livrabil | C1: Mastere EN cumulative | D1: Titluri trilingve cumulative | E1: Deadline | F1: Realizat — de completat | G1: Responsabil | H1: Observații
A2: 23–27 sept. | B2: Audit, canon, echipă, probe, finanțare | C2: 0 | D2: 0 | E2: 46292 | G2: De desemnat | H2: Scenariu condiționat de capacitate și finanțare
A3: 28 sept.–4 oct. | B3: 4 mastere pilot; scriere în paralel | C3: 4 | D3: 0 | E3: 46299 | G3: De desemnat | H3: Scenariu condiționat de capacitate și finanțare
A4: 5–11 oct. | B4: 17 existente + 20 noi; pilot trilingv | C4: 37 | D4: 4 | E4: 46306 | G4: De desemnat | H4: Scenariu condiționat de capacitate și finanțare
A5: 12–18 oct. | B5: 20 mastere noi; fond în traducere | C5: 57 | D5: 4 | E5: 46313 | G5: De desemnat | H5: Scenariu condiționat de capacitate și finanțare
A6: 19–25 oct. | B6: 77 mastere; 17 titluri trilingve | C6: 77 | D6: 17 | E6: 46320 | G6: De desemnat | H6: Scenariu condiționat de capacitate și finanțare
A7: 26 oct.–1 nov. | B7: 100 mastere; lot A disponibil | C7: 100 | D7: 37 | E7: 46327 | G7: De desemnat | H7: Scenariu condiționat de capacitate și finanțare
A8: 2–8 nov. | B8: Lot B trilingv | C8: 100 | D8: 57 | E8: 46334 | G8: De desemnat | H8: Scenariu condiționat de capacitate și finanțare
A9: 9–15 nov. | B9: Lot C trilingv | C9: 100 | D9: 77 | E9: 46341 | G9: De desemnat | H9: Scenariu condiționat de capacitate și finanțare
A10: 16–22 nov. | B10: Lot D trilingv | C10: 100 | D10: 92 | E10: 46348 | G10: De desemnat | H10: Scenariu condiționat de capacitate și finanțare
A11: 23–29 nov. | B11: 100 titluri până la 28.11 | C11: 100 | D11: 100 | E11: 46355 | G11: De desemnat | H11: Scenariu condiționat de capacitate și finanțare
A12: 30 nov.–1 dec. | B12: Audit și acceptare finală | C12: 100 | D12: 100 | E12: 46357 | G12: De desemnat | H12: Scenariu condiționat de capacitate și finanțare

Sheet Capacitate
A1: Activitate | B1: Volum | C1: Unitate | D1: Unități acceptate / oră | E1: Zile productive / persoană | F1: Ore productive / zi | G1: Ore necesare | H1: Echiv. persoane
A2: Scriere nouă acceptată | B2: =SUMIF(Catalog_100!F2:F101,"Nou",Catalog_100!I2:I101) -> 4440000 | C2: cuvinte | D2: 700 | E2: 25 | F2: 5 | G2: =B2/D2 -> 6342.8571 | H2: =ROUNDUP(G2/(E2*F2),0) -> 51
A3: Restructurare fond | B3: =SUMIF(Catalog_100!F2:F101,"Fond",Catalog_100!I2:I101) -> 979000 | C3: cuvinte | D3: 1000 | E3: 20 | F3: 5 | G3: =B3/D3 -> 979 | H3: =ROUNDUP(G3/(E3*F3),0) -> 10
A4: Editare EN | B4: =SUM(Catalog_100!I2:I101) -> 5419000 | C4: cuvinte | D4: 1500 | E4: 35 | F4: 5 | G4: =B4/D4 -> 3612.6667 | H4: =ROUNDUP(G4/(E4*F4),0) -> 21
A5: Corectură EN | B5: =SUM(Catalog_100!I2:I101) -> 5419000 | C5: cuvinte | D5: 2500 | E5: 35 | F5: 5 | G5: =B5/D5 -> 2167.6 | H5: =ROUNDUP(G5/(E5*F5),0) -> 13
A6: Traducere/posteditare | B6: =SUM(Catalog_100!I2:I101)*2 -> 10838000 | C6: cuvinte sursă | D6: 1000 | E6: 35 | F6: 5 | G6: =B6/D6 -> 10838 | H6: =ROUNDUP(G6/(E6*F6),0) -> 62
A7: Corectură traduceri | B7: =SUM(Catalog_100!I2:I101)*2 -> 10838000 | C7: cuvinte sursă | D7: 2500 | E7: 30 | F7: 5 | G7: =B7/D7 -> 4335.2 | H7: =ROUNDUP(G7/(E7*F7),0) -> 29
A8: Producție digitală | B8: =COUNTA(Editii_300!A2:A301) -> 300 | C8: ediții | D8: 0.16666667 | E8: 30 | F8: 5 | G8: =B8/D8 -> 1800 | H8: =ROUNDUP(G8/(E8*F8),0) -> 12
A9: QA final | B9: =COUNTA(Editii_300!A2:A301) -> 300 | C9: ediții | D9: 0.5 | E9: 25 | F9: 5 | G9: =B9/D9 -> 600 | H9: =ROUNDUP(G9/(E9*F9),0) -> 5
A11: TOTAL EXECUȚIE | H11: =SUM(H2:H9) -> 203
A13: Coordonare/design/marketing | H13: 12
A14: Total orientativ | H14: =H11+H13 -> 215
A16: Vitezele sunt ipoteze, nu standarde. Validare prin probe plătite. Persoanele nu pot fi numărate simultan în două roluri.
A19: Capacitate editorială. Dezvoltarea site-ului este un proiect separat; bugetul are doar o rezervă de integrare.

Sheet Buget
A1: Activitate | B1: Cantitate | C1: Tarif jos EUR | D1: Tarif bază EUR | E1: Tarif ridicat EUR | F1: Cost jos EUR | G1: Cost bază EUR | H1: Cost ridicat EUR | I1: Observație
A2: Scriere 83 titluri | B2: =SUMIF(Catalog_100!F2:F101,"Nou",Catalog_100!I2:I101) -> 4440000 | C2: 0.03 | D2: 0.06 | E2: 0.09 | F2: =B2*C2 -> 133200 | G2: =B2*D2 -> 266400 | H2: =B2*E2 -> 399600 | I2: Ipoteză; de înlocuit cu oferte
A3: Restructurare fond existent | B3: =SUMIF(Catalog_100!F2:F101,"Fond",Catalog_100!I2:I101) -> 979000 | C3: 0.006 | D3: 0.012 | E3: 0.02 | F3: =B3*C3 -> 5874 | G3: =B3*D3 -> 11748 | H3: =B3*E3 -> 19580 | I3: Ipoteză; de înlocuit cu oferte
A4: Editare EN | B4: =SUM(Catalog_100!I2:I101) -> 5419000 | C4: 0.01 | D4: 0.02 | E4: 0.03 | F4: =B4*C4 -> 54190 | G4: =B4*D4 -> 108380 | H4: =B4*E4 -> 162570 | I4: Ipoteză; de înlocuit cu oferte
A5: Corectură EN | B5: =SUM(Catalog_100!I2:I101) -> 5419000 | C5: 0.004 | D5: 0.008 | E5: 0.012 | F5: =B5*C5 -> 21676 | G5: =B5*D5 -> 43352 | H5: =B5*E5 -> 65028 | I5: Ipoteză; de înlocuit cu oferte
A6: Traducere / posteditare integrală | B6: =SUM(Catalog_100!I2:I101)*2 -> 10838000 | C6: 0.025 | D6: 0.05 | E6: 0.09 | F6: =B6*C6 -> 270950 | G6: =B6*D6 -> 541900 | H6: =B6*E6 -> 975420 | I6: Ipoteză; de înlocuit cu oferte
A7: Corectură independentă traduceri | B7: =SUM(Catalog_100!I2:I101)*2 -> 10838000 | C7: 0.006 | D7: 0.012 | E7: 0.018 | F7: =B7*C7 -> 65028 | G7: =B7*D7 -> 130056 | H7: =B7*E7 -> 195084 | I7: Ipoteză; de înlocuit cu oferte
A8: Design coperte originale | B8: =COUNTA(Catalog_100!A2:A101) -> 100 | C8: 200 | D8: 400 | E8: 700 | F8: =B8*C8 -> 20000 | G8: =B8*D8 -> 40000 | H8: =B8*E8 -> 70000 | I8: Ipoteză; de înlocuit cu oferte
A9: Localizare coperte | B9: =COUNTA(Catalog_100!A2:A101)*2 -> 200 | C9: 40 | D9: 75 | E9: 120 | F9: =B9*C9 -> 8000 | G9: =B9*D9 -> 15000 | H9: =B9*E9 -> 24000 | I9: Ipoteză; de înlocuit cu oferte
A10: EPUB și metadate | B10: =COUNTA(Editii_300!A2:A301) -> 300 | C10: 60 | D10: 120 | E10: 180 | F10: =B10*C10 -> 18000 | G10: =B10*D10 -> 36000 | H10: =B10*E10 -> 54000 | I10: Ipoteză; de înlocuit cu oferte
A11: QA final | B11: =COUNTA(Editii_300!A2:A301) -> 300 | C11: 20 | D11: 40 | E11: 60 | F11: =B11*C11 -> 6000 | G11: =B11*D11 -> 12000 | H11: =B11*E11 -> 18000 | I11: Ipoteză; de înlocuit cu oferte
A12: Coordonare/drepturi/administrare | B12: 1 | C12: 18000 | D12: 35000 | E12: 60000 | F12: =B12*C12 -> 18000 | G12: =B12*D12 -> 35000 | H12: =B12*E12 -> 60000 | I12: Ipoteză; de înlocuit cu oferte
A13: Comerț online și infrastructură | B13: 1 | C13: 5000 | D13: 12000 | E13: 20000 | F13: =B13*C13 -> 5000 | G13: =B13*D13 -> 12000 | H13: =B13*E13 -> 20000 | I13: Ipoteză; de înlocuit cu oferte
A14: Marketing test și lansare | B14: 1 | C14: 10000 | D14: 25000 | E14: 50000 | F14: =B14*C14 -> 10000 | G14: =B14*D14 -> 25000 | H14: =B14*E14 -> 50000 | I14: Ipoteză; de înlocuit cu oferte
A16: SUBTOTAL | F16: =SUM(F2:F14) -> 635918 | G16: =SUM(G2:G14) -> 1276836 | H16: =SUM(H2:H14) -> 2113282
A17: Rezervă | B17: 0.2 | F17: =F16*$B$17 -> 127183.6 | G17: =G16*$B$17 -> 255367.2 | H17: =H16*$B$17 -> 422656.4
A18: TOTAL CU REZERVĂ | F18: =F16+F17 -> 763101.6 | G18: =G16+G17 -> 1532203.2 | H18: =H16+H17 -> 2535938.4
A21: Fără taxe pe facturi, print/stoc sau audio. Rate ipotetice, nu oferte. Nu adăugați salariile aceleiași prestații peste tariful pe cuvânt.

Sheet Scenarii
A1: MODEL DE ABONAMENT — IPOTEZE, NU PROGNOZE
A2: Preț brut RON / lună | B2: 100 | C2: Tarif comunicat de beneficiar; Reader 10.
A3: Titluri deblocate lunar | B3: 10 | C3: Acces cât abonamentul este activ.
A4: Cotă taxă ipotetică | B4: 0.21 | C4: Sensibilitate, NU încadrare fiscală. Confirmați cu contabilul.
A5: Procesare plată RON | B5: 3 | C5: Ipoteză, nu ofertă de procesator.
A6: Cost variabil RON | B6: 8 | C6: Suport/infrastructură; de măsurat.
A7: Rezervă drepturi / net | B7: 0.1 | C7: Ipoteză contractuală.
A8: Cost fix lunar RON | B8: 30000 | C8: Nu include producția catalogului, marketingul sau noile titluri.
A9: Retenție lunară ipotetică | B9: 0.9 | C9: Se înlocuiește cu date de cohortă.
A10: Plafon CAC de test RON | B10: 60 | C10: Regulă conservatoare inițială, nu cost măsurat.
A11: Curs de planificare RON/EUR | B11: 5 | C11: NU cotație live și nu tarif de conversie pentru site.
A13: Venit net RON | B13: =B2/(1+B4) -> 82.644628
A14: Contribuție / abonat RON | B14: =B13*(1-B7)-B5-B6 -> 63.380165
A15: Prag operațional abonați | B15: =IF(B14>0,ROUNDUP(B8/B14,0),0) -> 474 | C15: Fără marketing, recuperarea catalogului și investiții viitoare; zero dacă marja este negativă nu înseamnă fezabilitate.
A16: Contribuție 6 luni estimată | B16: =B14*(1+B9+B9^2+B9^3+B9^4+B9^5) -> 296.97347
A17: O treime din contribuția 6 luni | B17: =B16/3 -> 98.991156
A18: Catalog bază RON | B18: =Buget!G18*B11 -> 7661016
A19: Luni-abonat pentru catalog | B19: =IF(B14>0,B18/B14,0) -> 120874.03 | C19: Înainte de cost fix și achiziție. NU durată de recuperare și NU abonați existenți.
A21: Abonați activi | B21: Încasări brute | C21: Contribuție | D21: După cost fix | E21: Luni recuperare înainte de CAC/noi cărți
A22: 200 | B22: =A22*$B$2 -> 20000 | C22: =A22*$B$14 -> 12676.033 | D22: =C22-$B$8 -> -17323.967 | E22: =IF(D22>0,$B$18/D22,0) -> 0
A23: 1000 | B23: =A23*$B$2 -> 100000 | C23: =A23*$B$14 -> 63380.165 | D23: =C23-$B$8 -> 33380.165 | E23: =IF(D23>0,$B$18/D23,0) -> 229.50803
A24: 3000 | B24: =A24*$B$2 -> 300000 | C24: =A24*$B$14 -> 190140.5 | D24: =C24-$B$8 -> 160140.5 | E24: =IF(D24>0,$B$18/D24,0) -> 47.839342
A25: 10000 | B25: =A25*$B$2 -> 1000000 | C25: =A25*$B$14 -> 633801.65 | D25: =C25-$B$8 -> 603801.65 | E25: =IF(D25>0,$B$18/D25,0) -> 12.687968
A27: 0 la recuperare = nerecuperabil în scenariul cu marjă operațională <= 0; nu înseamnă recuperare instantanee.

Sheet KPI
A1: Indicator | B1: Definiție | C1: Ipoteză / prag | D1: Interpretare | E1: Realizat
A2: Conversie abonat | B2: Plătitori noi / vizite calificate | C2: 0.02 | D2: Ipoteză, per limbă/canal
A3: Activare 72h | B3: Abonați care încep prima carte / abonați noi | C3: 0.6 | D3: Obiectiv de test
A4: Trecere vol.1→vol.2 | B4: Cititori vol.1 care încep vol.2 | C4: 0.35 | D4: Obiectiv de test; definiție cohortă consecventă
A5: Retenție lunară | B5: Reînnoiri / abonamente eligibile | C5: 0.9 | D5: Ipoteză; primul semnal abia la sfârșit de noiembrie
A6: CAC | B6: Cheltuieli de achiziție / abonați noi | C6: 60 | D6: RON; plafon inițial, nu rezultat
A7: Defecte critice | B7: Capitole lipsă / drepturi / traducere / acces | C7: 0 | D7: Prag obligatoriu înainte de lansare

Sheet Surse
A1: ID | B1: Sursă | C1: URL | D1: Utilizare / limită
A2: S1 | B2: AAP — StatShot Annual 2025 (10.08.2026) | C2: https://publishers.org/news/aap-statshot-annual-report-publishing-revenues-totaled-33-4-billion-for-calendar-year-2025/ | D2: Piața SUA: venituri, ficțiune adulți, copii/YA.
