Workbook

Sheet Dashboard
A1: Dashboard - Proiecție financiară PoCIDIF 2.1, grant 3.000.000 EUR
A3: KPI | B3: Valoare | C3: Țintă/limită | D3: Status
A4: Grant nerambursabil | B4: =Buget_eligibil!H15 -> 3000000 | C4: 3.000.000 EUR | D4: =IF(B4=3000000,"OK","REVIZUIRE") -> OK
A5: Cost eligibil total fără TVA | B5: =Buget_eligibil!E14 -> 4210715 | C5: model | D5: informativ
A6: Cofinanțare totală fără TVA | B6: =Buget_eligibil!H24 -> 1210715 | C6: > minim + 5% | D6: =Buget_eligibil!I29 -> OK - peste 5%
A7: Pondere echipamente în grant | B7: =Buget_eligibil!H22 -> 0.72 | C7: maximizată | D7: =IF(B7>=70%,"OK","OPTIMIZARE") -> OK
A8: Pondere activitate de bază | B8: =Buget_eligibil!H17 -> 0.9 | C8: >=80% | D8: =IF(B8>=80%,"OK","NU") -> OK
A9: Pondere personal tehnic propriu / bază | B9: =Buget_eligibil!H21 -> 0.2 | C9: >=20% | D9: =IF(B9>=20%,"OK","NU") -> OK
A10: Minimis total | B10: =Buget_eligibil!H18 -> 300000 | C10: <=300.000 EUR | D10: =IF(B10<=300000,"OK","NU") -> OK
A11: RI mediu post-implementare | B11: =Punctaj_ETF!C10 -> 0.18761659 | C11: >2% | D11: =IF(B11>2%,"OK","NU") -> OK
A12: PI_D | B12: =Punctaj_ETF!C12 -> 0.70739177 | C12: >0,5x | D12: =IF(B12>0.5,"OK","NU") -> OK
A13: Flux numerar cumulat minim durabilitate | B13: =Punctaj_ETF!C11 -> 480000 | C13: >0 | D13: =IF(B13>0,"OK","NU") -> OK
A16: Structură grant propus
A17: Categorie | B17: Grant EUR | C17: Pondere grant
A18: Echipamente linie producție + HPC | B18: =Buget_eligibil!H4+Buget_eligibil!H5 -> 2160000 | C18: =B18/$B$21 -> 0.72
A19: Personal tehnic propriu CDI | B19: =Buget_eligibil!H6 -> 540000 | C19: =B19/$B$21 -> 0.18
A20: Minimis conex/comercializare/audit | B20: =Buget_eligibil!H18 -> 300000 | C20: =B20/$B$21 -> 0.1
A21: Total | B21: =SUM(B18:B20) -> 3000000 | C21: =SUM(C18:C20) -> 1
A24: Curs valutar | B24: 1 Euro
A25: 1 euro = 5,0981 | B25: 5.0981

Sheet Ipoteze
A1: Ipoteze principale - proiecție proiect hardware inovativ PoCIDIF 2.1
A3: Parametru | B3: Valoare | C3: Unitate | D3: Comentariu
A4: Curs InforEuro | B4: 5.0981 | C4: RON/EUR | D4: Curs ghid mai 2026
A5: Finanțare nerambursabilă țintă | B5: 3000000 | C5: EUR | D5: Maxim pentru produs hardware inovativ
A6: Intensitate ajutor regional - micro/mică Alba | B6: 0.7 | C6: % | D6: Pentru echipamente/linie producție
A7: Intensitate CDI - cercetare industrială cu diseminare/licențiere | B7: 0.8 | C7: % | D7: Pentru personal tehnic propriu / activități CDI
A8: Intensitate minimis | B8: 1 | C8: % | D8: Plafon 300.000 EUR / întreprindere unică / 3 ani
A9: Plafon minimis | B9: 300000 | C9: EUR | D9: Limită de minimis
A10: Prag activitate de bază din grant total | B10: 0.8 | C10: % | D10: Minim 80%
A11: Prag personal tehnic propriu din activitate de bază | B11: 0.2 | C11: % | D11: Minim 20%
A12: Durată implementare | B12: 24 | C12: luni | D12: Ipoteză model
A13: Durabilitate post-implementare | B13: 3 | C13: ani | D13: Obligatoriu în proiecții
A14: Marjă minimă pentru punctaj RI maxim | B14: 0.02 | C14: % | D14: RI > 2%
A15: Performanță investiție minimă | B15: 0.5 | C15: x | D15: PI_D > 0,5
A16: Cofinanțare peste minim pentru punctaj maxim | B16: 0.05 | C16: % | D16: Țintă >5% peste minim

Sheet Buget_eligibil
A1: Buget eligibil orientativ - finanțare 3.000.000 EUR, maxim echipamente, respectare praguri
A3: Categorie | B3: Tip ajutor | C3: Activitate | D3: Domeniu intervenție | E3: Cost eligibil EUR | F3: Intensitate maximă | G3: Grant maxim EUR | H3: Grant propus EUR | I3: Cofinanțare EUR | J3: Observații
A4: Linie producție robotică / asamblare pilot hardware AI-edge | B4: Ajutor regional | C4: Introducere în producție | D4: 002 | E4: 2571429 | F4: 0.7 | G4: =E4*F4 -> 1800000.3 | H4: 1800000 | I4: =E4-H4 -> 771429 | J4: Echipamente principale; justifică depășirea pragului 1,5 mil. EUR
A5: Cluster HPC/GPU pentru antrenare și testare modele AI | B5: Ajutor regional | C5: Introducere în producție | D5: 002 | E5: 514286 | F5: 0.7 | G5: =E5*F5 -> 360000.2 | H5: 360000 | I5: =E5-H5 -> 154286 | J5: Servere GPU, stocare, rețea, securitate
A6: Personal tehnic propriu CDI - coordonator + experți | B6: CDI / cercetare industrială | C6: Activitate de bază CDI | D6: 010 | E6: 675000 | F6: 0.8 | G6: =E6*F6 -> 540000 | H6: 540000 | I6: =E6-H6 -> 135000 | J6: Exact 20% din grantul activității de bază
A7: Cercetare contractuală / testare certificare preliminară | B7: CDI / dezvoltare experimentală | C7: Activitate de bază CDI | D7: 010 | E7: 150000 | F7: 0.6 | G7: =E7*F7 -> 90000 | H7: 0 | I7: =E7-H7 -> 150000 | J7: Ținut ca rezervă eligibilă cu finanțare proprie pentru cofinanțare suplimentară
A8: Promovare/comercializare produs; go-to-market | B8: Minimis | C8: Introducere în piață | D8: 010 | E8: 120000 | F8: 1 | G8: =E8*F8 -> 120000 | H8: 120000 | I8: =E8-H8 -> 0 | J8: Obligatoriu pentru introducere în piață
A9: Audit tehnic, securitate, GDPR, testare nivele securitate | B9: Minimis | C9: Audit tehnic | D9: 010 | E9: 60000 | F9: 1 | G9: =E9*F9 -> 60000 | H9: 60000 | I9: =E9-H9 -> 0 | J9: Obligatoriu la final
A10: Informare și publicitate finanțare | B10: Minimis | C10: Informare/publicitate | D10: 010 | E10: 30000 | F10: 1 | G10: =E10*F10 -> 30000 | H10: 30000 | I10: =E10-H10 -> 0 | J10: Conform ghid vizibilitate
A11: Management proiect / consultanță implementare | B11: Minimis | C11: Management proiect | D11: 010 | E11: 90000 | F11: 1 | G11: =E11*F11 -> 90000 | H11: 90000 | I11: =E11-H11 -> 0 | J11: Sub prag 10%
A12: Accesibilizare produs pentru persoane cu dizabilități | B12: Minimis | C12: Accesibilizare | D12: 010 | E12: 0 | F12: 1 | G12: =E12*F12 -> 0 | H12: 0 | I12: =E12-H12 -> 0 | J12: Inclusă tehnic în module, fără buget separat în variantă limită
A14: TOTALURI ȘI TESTE LIMITĂ | E14: =SUM(E4:E12) -> 4210715 | G14: =SUM(G4:G12) -> 3090000.5 | H14: =SUM(H4:H12) -> 3000000 | I14: =SUM(I4:I12) -> 1210715
A15: Grant total propus | H15: =H14 -> 3000000 | J15: Trebuie să fie 3.000.000 EUR
A16: Grant activitate de bază | H16: =H4+H5+H6+H7 -> 2700000 | J16: Minim 80% din grant total
A17: Pondere activitate de bază în grant total | H17: =H16/H15 -> 0.9 | J17: OK dacă >=80%
A18: Grant minimis total | H18: =SUM(H8:H12) -> 300000 | J18: Maxim 300.000 EUR
A19: Consultanță + management minimis B2+B5 | H19: =H11 -> 90000 | J19: Maxim 10% din valoarea eligibilă/maxim eligibilă
A20: Personal tehnic propriu grant | H20: =H6 -> 540000 | J20: Minim 20% din grant activitate bază
A21: Pondere personal tehnic propriu / activitate bază | H21: =H20/H16 -> 0.2 | J21: OK dacă >=20%
A22: Pondere echipamente / grant total | H22: =(H4+H5)/H15 -> 0.72 | J22: Maximizare echipamente
A23: Grant echipamente regional | H23: =H4+H5 -> 2160000 | J23: Linie producție + HPC/GPU
A24: Cofinanțare totală propusă | H24: =I14 -> 1210715 | J24: Fără TVA
A25: Grant maxim teoretic pe buget | H25: =SUM(G4:G12) -> 3090000.5 | J25: Pentru calcul depășire cofinanțare minimă
A26: Cofinanțare minimă conform intensități | H26: =E14-H25 -> 1120714.5 | J26: Dacă s-ar cere maximul permis
H27: Excedent cofinanțare peste minim | I27: =H24-H26 -> 90000.5 | J27: EUR
H28: Procent excedent peste cofinanțare minimă | I28: =I27/H26 -> 0.080306358 | J28: %
H29: Status punctaj cofinanțare | I29: =IF(I28>Ipoteze!B16,"OK - peste 5%","INSUFICIENT") -> OK - peste 5%

Sheet Echipa
A1: Echipă minimă optimizată pentru punctaj maxim - ETF capacitate operațională
A3: Rol | B3: Tip | C3: Nr. persoane | D3: Experiență minimă țintă | E3: Cost/lună/pers EUR | F3: Luni | G3: Cost total EUR | H3: Grant alocat EUR | I3: Motiv punctaj
A4: Coordonator tehnic / arhitect robotică AI-edge | B4: tehnic propriu | C4: 1 | D4: >5 ani sau 2 proiecte similare | E4: 10000 | F4: 24 | G4: =C4*E4*F4 -> 240000 | H4: =G4*0.8 -> 192000 | I4: Cerință max: coordonator calificat cu experiență >5 ani
A5: Expert AI/ML & perception | B5: tehnic propriu | C5: 1 | D5: >2 ani | E5: 7500 | F5: 24 | G5: =C5*E5*F5 -> 180000 | H5: =G5*0.8 -> 144000 | I5: Expert tehnic 1
A6: Expert embedded/edge/firmware | B6: tehnic propriu | C6: 1 | D6: >2 ani | E6: 7500 | F6: 24 | G6: =C6*E6*F6 -> 180000 | H6: =G6*0.8 -> 144000 | I6: Expert tehnic 2
A7: Expert robotică/integrare senzori | B7: tehnic propriu | C7: 1 | D7: >3 ani sector vizat | E7: 5000 | F7: 24 | G7: =C7*E7*F7 -> 120000 | H7: =G7*0.8 -> 96000 | I7: Expert sectorial/tehnic pentru validare relevanță produs
A8: QA/Security engineer | B8: tehnic propriu | C8: 1 | D8: >2 ani | E8: 2500 | F8: 24 | G8: =C8*E8*F8 -> 60000 | H8: =G8*0.8 -> 48000 | I8: Testare, securitate, calitate
A9: Manager proiect | B9: management minimis | C9: 1 | D9: >5 ani fonduri/IT | E9: 4000 | F9: 18 | G9: =C9*E9*F9 -> 72000 | H9: =G9 -> 72000 | I9: Management proiect
A10: Responsabil financiar/achiziții | B10: management minimis | C10: 1 | D10: >3 ani | E10: 1000 | F10: 18 | G10: =C10*E10*F10 -> 18000 | H10: =G10 -> 18000 | I10: Achiziții, raportare, eligibilitate
A12: Total echipă tehnică proprie | E12: =SUM(G4:G8) -> 780000 | F12: =SUM(H4:H8) -> 624000
A13: Grant tehnic propriu bugetat în Buget_eligibil | F13: =Buget_eligibil!H6 -> 540000
A14: Diferență grant tehnic | F14: =F12-F13 -> 84000
A15: Status minim 20% activitate de bază | F15: =IF(F13>=Buget_eligibil!H16*Ipoteze!B11,"OK", "INSUFICIENT") -> OK
A16: Număr total persoane tehnice proprii | E16: =SUM(C4:C8) -> 5
A17: Număr minim ghid: coordonator + 2 experți | E17: 3
A18: Status echipă ETF | F18: =IF(E16>=3,"OK - peste minim", "INSUFICIENT") -> OK - peste minim

Sheet Proiectii_financiare
A1: Proiecții financiare proiect hardware inovativ - 24 luni implementare + 3 ani durabilitate
A3: Linie | B3: Preimplementare An 0 | C3: Implementare An 1 | D3: Implementare An 2 | E3: Durabilitate An 1 | F3: Durabilitate An 2 | G3: Durabilitate An 3 | H3: Observații
A4: Venituri fără proiect | B4: 500000 | C4: 520000 | D4: 540000 | E4: 560000 | F4: 580000 | G4: 600000 | H4: Ipoteză de bază societate
A5: Venituri generate de proiect | B5: 0 | C5: 0 | D5: 150000 | E5: 900000 | F5: 1450000 | G5: 2100000 | H5: Contracte pilot, licențe, vânzări hardware + SaaS
A6: Venituri totale cu proiect | B6: =B4+B5 -> 500000 | C6: =C4+C5 -> 520000 | D6: =D4+D5 -> 690000 | E6: =E4+E5 -> 1460000 | F6: =F4+F5 -> 2030000 | G6: =G4+G5 -> 2700000
A7: Cheltuieli exploatare fără proiect | B7: 420000 | C7: 430000 | D7: 440000 | E7: 455000 | F7: 470000 | G7: 485000 | H7: Costuri curente
A8: Cheltuieli operare proiect | B8: 0 | C8: 30000 | D8: 80000 | E8: 420000 | F8: 680000 | G8: 980000 | H8: Personal operare, cloud, service, vânzări
A9: Cheltuieli totale exploatare cu proiect | B9: =B7+B8 -> 420000 | C9: =C7+C8 -> 460000 | D9: =D7+D8 -> 520000 | E9: =E7+E8 -> 875000 | F9: =F7+F8 -> 1150000 | G9: =G7+G8 -> 1465000
A10: Profit exploatare fără proiect | B10: =B4-B7 -> 80000 | C10: =C4-C7 -> 90000 | D10: =D4-D7 -> 100000 | E10: =E4-E7 -> 105000 | F10: =F4-F7 -> 110000 | G10: =G4-G7 -> 115000
A11: Profit exploatare cu proiect | B11: =B6-B9 -> 80000 | C11: =C6-C9 -> 60000 | D11: =D6-D9 -> 170000 | E11: =E6-E9 -> 585000 | F11: =F6-F9 -> 880000 | G11: =G6-G9 -> 1235000
A12: Profit exploatare incremental | B12: =B11-B10 -> 0 | C12: =C11-C10 -> -30000 | D12: =D11-D10 -> 70000 | E12: =E11-E10 -> 480000 | F12: =F11-F10 -> 770000 | G12: =G11-G10 -> 1120000 | H12: Folosit pentru RI
A13: Cost investiție eligibil proiect | C13: =Buget_eligibil!E14/2 -> 2105357.5 | D13: =Buget_eligibil!E14/2 -> 2105357.5 | E13: 0 | F13: 0 | G13: 0 | H13: Implementare 24 luni
A14: Grant încasat estimat | C14: =Buget_eligibil!H15*45% -> 1350000 | D14: =Buget_eligibil!H15*55% -> 1650000 | E14: 0 | F14: 0 | G14: 0 | H14: Tranșe rambursare/plată
A15: Cofinanțare și neeligibile plătite | C15: =Buget_eligibil!H24*50% -> 605357.5 | D15: =Buget_eligibil!H24*50% -> 605357.5 | E15: 0 | F15: 0 | G15: 0 | H15: Fără TVA
A16: Flux numerar operațional proiect | B16: =B12 -> 0 | C16: =C12 -> -30000 | D16: =D12 -> 70000 | E16: =E12 -> 480000 | F16: =F12 -> 770000 | G16: =G12 -> 1120000
A17: Flux numerar net anual proiect | B17: =B15 -> 0 | C17: =C15+C14-C13-C8 -> -180000 | D17: =D15+D14-D13-D8 -> 70000 | E17: =E16 -> 480000 | F17: =E17+F16 -> 1250000 | G17: =F17+G16 -> 2370000 | H17: Simplificat: include investiție, grant, operare
A18: Flux numerar net cumulat | B18: =B16 -> 0 | C18: =B17+C16 -> -30000 | D18: =C17+D16 -> -110000 | E18: =D17+E16 -> 550000 | F18: =E17+F16 -> 1250000 | G18: =F17+G16 -> 2370000 | H18: Trebuie pozitiv în anii de durabilitate
A19: Dovezi comercializare cumulative | B19: 0 | C19: 0 | D19: 1 | E19: 3 | F19: 6 | G19: 10 | H19: Țintă minimă: 3 dovezi

Sheet Punctaj_ETF
A1: Indicatori de conformare și punctaj maxim - ETF
A3: Criteriu / Limită | B3: Formula / Test | C3: Rezultat | D3: Status | E3: Punctaj țintă | F3: Justificare de inclus în Planul de afaceri | G3: Risc | H3: Acțiune
A4: Grant maxim hardware | B4: =Buget_eligibil!H15 -> 3000000 | C4: =Buget_eligibil!H15 -> 3000000 | D4: =IF(C4=3000000,"OK","REVIZUIRE") -> OK | E4: Max permis | F4: Produs hardware inovativ + linie de producție | G4: Dacă produsul e încadrat software, plafonul scade la 1,5 mil. EUR | H4: Documentație tehnică hardware clară
A5: Activitate bază >=80% grant | B5: =Buget_eligibil!H17 -> 0.9 | C5: =Buget_eligibil!H17 -> 0.9 | D5: =IF(C5>=80%,"OK","NU") -> OK | E5: Eligibilitate | F5: Baza conține echipamente + CDI + introducere producție | G5: Încadrare greșită a activităților conexe | H5: Corelare Anexa 6 cu activități
A6: Minimis <=300.000 EUR | B6: =Buget_eligibil!H18 -> 300000 | C6: =Buget_eligibil!H18 -> 300000 | D6: =IF(C6<=300000,"OK","NU") -> OK | E6: Eligibilitate | F6: Minimis folosit exact pe publicitate, go-to-market, audit, management | G6: Depășire la nivel întreprindere unică | H6: Verificare ajutoare anterioare
A7: Personal tehnic propriu >=20% bază | B7: =Buget_eligibil!H21 -> 0.2 | C7: =Buget_eligibil!H21 -> 0.2 | D7: =IF(C7>=20%,"OK","NU") -> OK | E7: Eligibilitate + capacitate | F7: 5 persoane tehnice proprii; grant 540k = 20% din bază | G7: CV-uri slabe / necorelate | H7: CV + certificări + proiecte relevante
A8: Echipamente / grant total | B8: =Buget_eligibil!H22 -> 0.72 | C8: =Buget_eligibil!H22 -> 0.72 | D8: =IF(C8>=70%,"OK","OPTIMIZARE") -> OK | E8: Max echipamente | F8: 72% din grant merge în echipamente și linie producție | G8: Echipamente nejustificate sau prețuri nerezonabile | H8: 2 oferte solide + studii piață
A9: Cofinanțare peste minim >5% | B9: =Buget_eligibil!H28 -> Procent excedent peste cofinanțare minimă | C9: =Buget_eligibil!H28 -> Procent excedent peste cofinanțare minimă | D9: =IF(C9>5%,"OK","NU") -> OK | E9: 5/5 | F9: Bugetul include contribuție proprie suplimentară pentru punctaj | G9: Cash insuficient la contractare | H9: Extras cont/linie credit
A10: RI >2% | B10: =AVERAGE(Proiectii_financiare!E12:G12)/Buget_eligibil!E14 -> 0.18761659 | C10: =AVERAGE(Proiectii_financiare!E12:G12)/Buget_eligibil!E14 -> 0.18761659 | D10: =IF(C10>2%,"OK","NU") -> OK | E10: 5/5 | F10: Profit incremental mediu >2% din valoarea proiectului | G10: Venituri nefundamentate | H10: Contracte pilot, LOI, studii piață
A11: Flux numerar cumulat pozitiv durabilitate | B11: =MIN(Proiectii_financiare!E17:G17) -> 480000 | C11: =MIN(Proiectii_financiare!E17:G17) -> 480000 | D11: =IF(C11>0,"OK","NU") -> OK | E11: 5/5 | F11: Cash pozitiv pe toată durabilitatea | G11: Subestimare operare | H11: Buget mentenanță realist
A12: PI_D >0,5 | B12: =SUM(Proiectii_financiare!E5:G5)/(Buget_eligibil!E14+SUM(Proiectii_financiare!E8:G8)) -> 0.70739177 | C12: =SUM(Proiectii_financiare!E5:G5)/(Buget_eligibil!E14+SUM(Proiectii_financiare!E8:G8)) -> 0.70739177 | D12: =IF(C12>0.5,"OK","NU") -> OK | E12: Indicator rezultat | F12: Venituri directe/indirecte suficiente vs dezvoltare + exploatare | G12: Neatingere indicator | H12: Minimum 3 contracte/facturi în primul an
A13: Dovezi comercializare >=3 | B13: =MAX(Proiectii_financiare!E21:G21) -> 0 | C13: =MAX(Proiectii_financiare!E21:G21) -> 0 | D13: =IF(C13>=3,"OK","NU") -> NU | E13: Eligibilitate rezultat | F13: 3 dovezi în anul 1 durabilitate; 10 până în anul 3 | G13: Proforme/LOI nu sunt dovezi | H13: Contracte/facturi reale

Sheet Surse
A1: Sursă | B1: Referință internă | C1: Element folosit în model | D1: Observații
A2: Ghid Acțiunea 2.1 PoCIDIF.pdf | B2: secțiunea 5.3.2 / pag. 41-44 | C2: Categorii cheltuieli eligibile; hardware TIC, HPC, AI, edge, IoT, sisteme autonome/robotizate; praguri 80%, minimis 300.000 EUR, 20% personal tehnic propriu | D2: Document încărcat de utilizator
A3: Ghid Acțiunea 2.1 PoCIDIF.pdf | B3: secțiunea 5.4 / pag. 47 | C3: Finanțare maximă 3.000.000 EUR pentru produs hardware inovativ; peste 1.500.000 EUR justificare prin linie de producție | D3: Document încărcat de utilizator
A4: Ghid Acțiunea 2.1 PoCIDIF.pdf | B4: secțiunea 8.4 / pag. 59-70 | C4: Criterii ETF: inovație, PMF, calitatea bugetului, echipă, RI, sustenabilitate, scalare | D4: Document încărcat de utilizator
A5: Anexa 4 - Model Plan de afaceri.docx | B5: secțiunea D | C5: Proiecții financiare pe 3 ani, flux de numerar, RI și sustenabilitate | D5: Document încărcat de utilizator
A6: Anexa 1 - Cerere finanțare.docx | B6: secțiunea Buget / Indicatori / ETF | C6: Structura MySMIS: buget, domenii intervenție 002/006/010, autoevaluare ETF | D6: Document încărcat de utilizator
A7: Ipoteză de lucru | B7: n/a | C7: Solicitant micro/întreprindere mică, județ Alba, produs hardware inovativ, intensitate regională 70%, CDI 80%, minimis 100% | D7: Ipoteză ajustabilă
A8: Ipoteză de lucru | B8: n/a | C8: Valorile sunt fără TVA; TVA se tratează separat în funcție de deductibilitate | D8: Ipoteză ajustabilă

Sheet Salarii
A2: ANEXA 9
A4: HOTĂRÂRE Nr. 8/2018 din 10 ianuarie 2018 privind modificarea și completarea Hotărârii Guvernului nr. 583/2015 actualizată
A6: Nr.crt. | B6: Categoria de activități | C6: Nivel studii | D6: Funcția | E6: Limita maxima euro/ora | F6: 172 | G6: =Dashboard!B25 -> 5.0981 | H6: Salariu Complet | I6: Echivalare
A7: 1 | B7: Activități ce presupun nivelul înalt al creativitătii si/sau experiența și abilitate de conducere/management | C7: superioare | D7: Director, membru în echipa de management pe funcțiile definite în cererea de finanțare CS I, CS II, IDT I, IDT II, | E7: 50 | F7: =E7*F6 -> 8600 | G7: =F7*G6 -> 43843.66 | H7: =C58 -> 44829 | I7: Doctorat sau doctorand în faza finală (cu lucrarea depusa in vederea publicării) + peste 10 ani de experiența în unul din domeniile principale ale proiectului țintă sau Director proiect cu experiența de peste 15 ani în unul din domeniile principale ale proiectului ținta
A8: 2 | B8: Activități ce presupun cunoașterea aprofundata a metodelor de analiza și sinteza, precum și abilități de utilizare a acestora | C8: superioare | D8: Șef proiect, responsabil juridic/tehnic/achiziții/financiar proiect CS III, IDT III, CS, IDT | E8: 35 | F8: =E8*F6 -> 6020 | G8: =F8*G6 -> 30690.562 | H8: =C75 -> 31381 | I8: Master în Științe în unul din domeniile principale ale proiectului ținta sau peste 10 ani de experiența în unul din domeniile principale ale proiectului țintă
A9: 3 | B9: Activități ce presupun cunoașterea metodelor de analiza și sinteza a metodologiilor cercetarii, precum și abilitati de utilizare a acestora | C9: superioare | D9: Asistent de cercetare, doctorand, masterand | E9: 25 | F9: =E9*F6 -> 4300 | G9: =F9*G6 -> 21921.83 | H9: =C92 -> 22414 | I9: Absolvent in domeniul țintă sau în unul din domeniile principale ale proiectului țintă + peste 5 ani de experiența în domeniul țintă
A10: 4 | B10: Activități suport | C10: Superioare sau medii | D10: Tehnicieni, studenți, altele | E10: 15 | F10: =E10*F6 -> 2580 | G10: =F10*G6 -> 13153.098 | H10: =C110 -> 13449 | I10: Experiența minimă în domeniul țintă
A12: NOTE:
A13: 1. Limita maximă cuprinde toate taxele și impozitele datorate de angajat și se aplică tuturor veniturilor realizate de către o persoană pentru participarea la unul sau mai multe proiecte în cadrul PNCDI III, cu respectarea prevederilor legislației muncii.
A14: 2. Sumele în lei reprezentând costurile salariale directe se stabilesc la data perfectării sau actualizării contractului, în funcție de ultimul curs de schimb valutar comunicat de Banca Națională a României pentru 1 euro.
A16: Echivalențe :
A17: CSI- Doctorat+ experiența extensivă ( Coordonator științific, expert senior)
A18: CSII- Doctorat+ experiența avansată ( Coordonator activități, expert cercetare)
A19: IDTI- Inginer cu experiență de nivel înalt ( arhitect soluție/inginer senior/manager tehnic)
A20: IDTII- inginer cu experiența medie ( inginer software/hardware/developer specialist)
A21: CSIII – doctorand, nivel experiența medie ( cercetător junior)
A22: IDTIII- Inginer cu experiența 1-3 ani, medie ( inginer implementare, dezvoltator junior)
A23: CS – asistent cercetare, suport științific ( absolvent master/doctorand - experiența începător)
A24: IDT- absolvent licența/ dezvoltator junior/suport tehnic
... A48: Anul 2026 - iulie
A49: ANGAJAT | C49: Lei | D49: Euro
A50: Salariu Brut | C50: 43843 | D50: 8375.62
A51: Asigurari Sociale (CAS) | B51: 0.25 | C51: 10961 | D51: 2093.95
A52: Asigurari Sociale de Sanatate (CASS) | B52: 0.1 | C52: 4384 | D52: 837.5
A53: Deducere personala (DP) | C53: 0 | D53: 0
A54: Impozit pe venit (IV) | B54: 0.1 | C54: 2850 | D54: 544.45
A55: Salariu Net | C55: 25648 | D55: 4899.71
A56: ANGAJATOR | C56: Lei | D56: Euro
A57: Contributie Asiguratorie pentru Munca (CAM) | B57: 2.25% | C57: 986 | D57: 188.36
A58: Salariu Complet | C58: 44829 | D58: 8563.98
A59: TOTAL TAXE | C59: Lei | D59: Euro
A60: Angajatul plateste statului | C60: 18195 | D60: 3475.91
A61: Angajatorul plateste statului | C61: 986 | D61: 188.36
A62: Total taxe incasate de stat | C62: 19181 | D62: 3664.27
A63: Pentru a plati un salariu net de 25648 lei, angajatorul cheltuie 44829 lei
A65: Anul 2026 - iulie
A66: ANGAJAT | C66: Lei | D66: Euro
A67: Salariu Brut | C67: 30690 | D67: 5863.02
A68: Asigurari Sociale (CAS) | B68: 0.25 | C68: 7673 | D68: 1465.85
A69: Asigurari Sociale de Sanatate (CASS) | B69: 0.1 | C69: 3069 | D69: 586.3
...
